Workbook

Sheet IS Raw
C5: Tiêu đề
C6: Ngày xuất dữ liệu | J6: 1000000000
J7: 0.071963067 | K7: 0.59816546 | L7: 0.29260159 | M7: -0.014316251 | N7: 0.28097852
C8: Mã CK | D8: DBD | F8: Xem theo | G8: Năm | H8: 2018 | J8: 1225.14 | K8: 1385.5 | L8: 1388.52 | M8: 1401.01 | N8: 1262.01
C9: Loại | D9: Hợp nhất | F9: Tiền tệ | G9: VNĐ | H9: VNĐ | M9: 1256952371543
D11: 2009 | E11: 2010 | F11: 2011 | G11: 2012 | H11: 2013 | I11: 2014 | J11: 2015 | K11: 2016 | L11: 2017 | M11: 2018 | N11: 2019 | O11: 2020 | P11: 2021
C12: Trạng thái kiểm toán | D12: Đã kiểm toán | E12: Đã kiểm toán | F12: Đã kiểm toán | G12: Đã kiểm toán | H12: Đã kiểm toán | I12: Đã kiểm toán | J12: Đã kiểm toán | K12: Đã kiểm toán | L12: Đã kiểm toán | M12: Đã kiểm toán | N12: Đã kiểm toán | O12: Đã kiểm toán | P12: Đã kiểm toán
C13: Công ty Kiểm toán | G13: Kiểm toán AASC | H13: Kiểm toán AASC | I13: Kiểm toán AASC | J13: Kiểm toán AASC | K13: Kiểm toán AASC | L13: Kiểm toán AASC | M13: Kiểm toán AASC | N13: Kiểm toán AASC | O13: Kiểm toán AASC | P13: Kiểm toán AASC
C14: Loại Ý kiến Kiểm toán | G14: N/A | H14: Chấp nhận toàn phần | I14: Chấp nhận toàn phần | J14: Chấp nhận toàn phần | K14: Chấp nhận toàn phần | L14: Chấp nhận toàn phần | M14: Chấp nhận toàn phần | N14: Chấp nhận toàn phần | O14: Chấp nhận toàn phần | P14: Chấp nhận toàn phần
C15: Doanh số | D15: 1365.0395 | E15: 1649.6384 | F15: 1786.8936 | G15: 1739.0177 | H15: 2145.0329 | I15: 2452.8286 | J15: 1266.1456 | K15: 1442.5093 | L15: 1459.5214 | M15: 1474.019 | N15: 1321.0062 | O15: 1329.7752 | P15: 0
C16: Các khoản giảm trừ | D16: -2.2321604 | E16: -3.6416401 | F16: -2.5402983 | G16: -0.49021099 | H16: -0.86816562 | I16: -0.94931483 | J16: -41.077583 | K16: -57.607455 | L16: -71.294045 | M16: -72.994715 | N16: -59.277208 | O16: -72.82279 | P16: 0
C17: Doanh số thuần | D17: 1362.8073 | E17: 1645.9968 | F17: 1784.3533 | G17: 1738.5275 | H17: 2144.1647 | I17: 2451.8793 | J17: 1225.068 | K17: 1384.9018 | L17: 1388.2274 | M17: 1401.0243 | N17: 1261.729 | O17: 1256.9524 | P17: 1558.5043
C18: Doanh thu dược phẩm | J18: 1119.03 | K18: 1260.14 | L18: 1255.63 | M18: 1220.84 | N18: 1143.14 | O18: 1148.3 | P18: 1191.05
C19: Doanh thu vật tư y tế | J19: 94.46 | K19: 115.1 | L19: 117.07 | M19: 169.49 | N19: 103.75 | O19: 92.31 | P19: 352.87
C20: Doanh thu khác | J20: 11.65 | K20: 10.26 | L20: 15.82 | M20: 10.68 | N20: 15.12 | O20: 16.35 | P20: 14.58
C21: Giá vốn hàng bán | D21: -1238.4551 | E21: -1469.5634 | F21: -1554.1667 | G21: -1520.0936 | H21: -1869.0719 | I21: -2128.8437 | J21: -773.07692 | K21: -875.70244 | L21: -897.55493 | M21: -972.89628 | N21: -846.93308 | O21: -765.81309 | P21: -935.93871
C22: Giá vốn dược phẩm | J22: 674.4237 | K22: 753.29845 | L22: 767.29591 | M22: 782.32085 | N22: 728.5726 | O22: 669.32143 | P22: 597.8722
C23: Giá vốn vật tư y tế | J23: 88.907278 | K23: 108.55258 | L23: 113.70558 | M23: 179.61155 | N23: 104.47008 | O23: 83.476642 | P23: 323.75084
C24: Giá vốn khác | J24: 9.7459408 | K24: 13.851407 | L24: 16.553434 | M24: 10.963883 | N24: 13.8904 | O24: 13.015024 | P24: 14.315668
C25: Lãi gộp | D25: 124.35226 | E25: 176.43338 | F25: 230.18661 | G25: 218.43393 | H25: 275.0928 | I25: 323.03559 | J25: 451.99112 | K25: 509.1994 | L25: 490.67247 | M25: 428.12804 | N25: 414.79594 | O25: 491.13928 | P25: 0
C26: Thu nhập tài chính | D26: 11.54075 | E26: 6.2530333 | F26: 7.5311207 | G26: 5.855125 | H26: 3.6704648 | I26: 4.2809301 | J26: 17.714871 | K26: 16.213594 | L26: 18.773405 | M26: 16.074493 | N26: 13.251147 | O26: 7.7517822 | P26: 6.3201839
C27: Chi phí tài chính | D27: -36.268105 | E27: -39.16598 | F27: -55.878307 | G27: -31.547993 | H27: -23.772301 | I27: -30.303225 | J27: -15.816123 | K27: -9.1025277 | L27: -10.811343 | M27: -12.200034 | N27: -14.622931 | O27: -14.325531 | P27: -8.647017
C28: Trong đó: Chi phí lãi vay | D28: -28.02467 | E28: -36.630793 | F28: -45.318451 | G28: -30.49184 | H28: -19.654885 | I28: -25.505476 | J28: -5.4477753 | K28: -4.498013 | L28: -6.8281941 | M28: -8.3658397 | N28: -10.314155 | O28: -6.5888547 | P28: 0
C29: Lãi/(lỗ) từ công ty liên doanh (từ năm 2015) | D29: 0 | E29: 0 | F29: 0 | G29: 0 | H29: 0 | I29: 0 | J29: 0 | K29: 10.724382 | L29: 8.0301361 | M29: 10.579769 | N29: 14.43949 | O29: 15.238404 | P29: 16.083129
C30: Chi phí bán hàng | D30: -40.333567 | E30: -51.05357 | F30: -63.830106 | G30: -67.539288 | H30: -68.628661 | I30: -83.251927 | J30: -222.0959 | K30: -260.80345 | L30: -210.95744 | M30: -174.04986 | N30: -169.93779 | O30: -220.85513 | P30: -276.43932
C31: Chi phí quản lý doanh nghiệp | D31: -40.655915 | E31: -43.689503 | F31: -49.310941 | G31: -58.072038 | H31: -62.676267 | I31: -71.410843 | J31: -102.01819 | K31: -90.386997 | L31: -92.776906 | M31: -67.52121 | N31: -84.108598 | O31: -88.501076 | P31: -128.99778
C32: Lãi/(lỗ) từ hoạt động kinh doanh | D32: 18.635418 | E32: 48.777361 | F32: 68.698375 | G32: 67.129732 | H32: 123.68604 | I32: 142.35052 | J32: 129.77578 | K32: 175.84439 | L32: 202.93032 | M32: 201.0112 | N32: 173.81726 | O32: 190.44773 | P32: 230.88482
C33: Thu nhập khác | D33: 4.7799168 | E33: 5.8330356 | F33: 7.3574941 | G33: 23.189036 | H33: 6.2556639 | I33: 8.7732738 | J33: 144.1416 | K33: 0.22343835 | L33: 0.68875095 | M33: 0.23141078 | N33: 0.34645156 | O33: 2.8734188 | P33: 1.8696857
C34: Chi phí khác | D34: -0.94818806 | E34: -2.0307211 | F34: -2.9170078 | G34: -3.0392074 | H34: -1.5028517 | I34: -0.98062655 | J34: -0.061872556 | K34: -0.1867886 | L34: -0.022626147 | M34: -0.21626276 | N34: -0.15042521 | O34: -0.12983325 | P34: 0.30660157
C35: Thu nhập khác, ròng | D35: 3.8317287 | E35: 3.8023144 | F35: 4.4404864 | G35: 20.149829 | H35: 4.7528122 | I35: 7.7926473 | J35: 144.07973 | K35: 0.036649756 | L35: 0.6661248 | M35: 0.015148018 | N35: 0.19602636 | O35: 2.7435855 | P35: 0
C36: Lãi/(lỗ) từ công ty liên doanh | D36: 0 | E36: 0 | F36: 0 | G36: 0 | H36: 0 | I36: 0 | J36: 0 | K36: 0 | L36: 0 | M36: 0 | N36: 0 | O36: 0 | P36: 0
... C45: Lãi trên cổ phiếu pha loãng (VND) | D45: 0 | E45: 0 | F45: 0 | G45: 0 | H45: 0 | I45: 0 | J45: 0 | K45: 0 | L45: 0 | M45: 0 | N45: 0 | O45: 2712 | P45: 0
C47: STOXPLUS CORPORATION
C48: Trụ sở: Tầng 5, Tòa nhà Anh Minh, 36 Hoàng Cầu, Đống Đa, Hà Nội
C49: Chi nhánh TP HCM: Tầng 2 May Plaza - 63D Võ Văn Tần, Phường 6, Quận 3, TP.HCM
C50: Email: Stoxplus@StoxPlus.com
C52: TRUNG TÂM CHĂM SÓC KHÁCH HÀNG
C53: Tại Hà Nội
C54: Ms. Đỗ Thị Lan - chuyên viên chăm sóc Khách hàng
C55: T: (844) - 3562 6962 - Ext: 103 M: 0989 219 401
...

Sheet BS Raw
C5: Tiêu đề
C6: Ngày xuất dữ liệu | P6: 1000000000
P7: 48716.392
C8: Mã CK | D8: DBD | F8: Xem theo | G8: Năm | H8: 2018 | K8: 112-114-117-127-130
C9: Loại | D9: Hợp nhất | F9: Tiền tệ | G9: VNĐ | H9: VNĐ
J10: 106.71933 | K10: 156.02776 | L10: 204.07064 | M10: 249.38578 | N10: 281.75467 | O10: 326.31663 | P10: 412.21559
D11: 2009 | E11: 2010 | F11: 2011 | G11: 2012 | H11: 2013 | I11: 2014 | J11: 2015 | K11: 2016 | L11: 2017 | M11: 2018 | N11: 2019 | O11: 2020 | P11: 2021
C12: Trạng thái kiểm toán | D12: Đã kiểm toán | E12: Đã kiểm toán | F12: Đã kiểm toán | G12: Đã kiểm toán | H12: Đã kiểm toán | I12: Đã kiểm toán | J12: Đã kiểm toán | K12: Đã kiểm toán | L12: Đã kiểm toán | M12: Đã kiểm toán | N12: Đã kiểm toán | O12: Đã kiểm toán | P12: Đã kiểm toán
C13: Công ty Kiểm toán | G13: Kiểm toán AASC | H13: Kiểm toán AASC | I13: Kiểm toán AASC | J13: Kiểm toán AASC | K13: Kiểm toán AASC | L13: Kiểm toán AASC | M13: Kiểm toán AASC | N13: Kiểm toán AASC | O13: Kiểm toán AASC | P13: Kiểm toán AASC
C14: Loại Ý kiến Kiểm toán | G14: N/A | H14: Chấp nhận toàn phần | I14: Chấp nhận toàn phần | J14: Chấp nhận toàn phần | K14: Chấp nhận toàn phần | L14: Chấp nhận toàn phần | M14: Chấp nhận toàn phần | N14: Chấp nhận toàn phần | O14: Chấp nhận toàn phần | P14: Chấp nhận toàn phần
C15: TÀI SẢN NGẮN HẠN | D15: 304.08162 | E15: 425.4692 | F15: 430.74773 | G15: 540.80049 | H15: 639.36504 | I15: 756.45028 | J15: 772.56636 | K15: 1023.14 | L15: 1115.4177 | M15: 1021.2372 | N15: 1028.8082 | O15: 835.84574 | P15: 972.31054
C16: Tiền và tương đương tiền | D16: 21.196006 | E16: 44.016582 | F16: 36.96126 | G16: 98.834989 | H16: 100.57208 | I16: 127.49809 | J16: 210.69177 | K16: 135.54888 | L16: 96.499799 | M16: 92.556725 | N16: 138.16218 | O16: 108.72871 | P16: 68.45378
C17: Tiền | D17: 21.196006 | E17: 44.016582 | F17: 36.96126 | G17: 47.3021 | H17: 100.57208 | I17: 56.371803 | J17: 53.691771 | K17: 63.048882 | L17: 53.999799 | M17: 80.556725 | N17: 47.442333 | O17: 35.184671 | P17: 31.45378
C18: Các khoản tương đương tiền | D18: 0 | E18: 0 | F18: 0 | G18: 51.53289 | H18: 0 | I18: 71.126283 | J18: 157 | K18: 72.5 | L18: 42.5 | M18: 12 | N18: 90.719845 | O18: 73.544044 | P18: 37
C19: Giá trị thuần đầu tư ngắn hạn | D19: 4.2701751 | E19: 4.2419197 | F19: 3.8007988 | G19: 4.2409005 | H19: 3.4392469 | I19: 0.8737981 | J19: 110.00139 | K19: 274.11239 | L19: 313.80139 | M19: 222.70139 | N19: 113.94139 | O19: 93.341393 | P19: 139.20139
C20: Đầu tư ngắn hạn | D20: 8.0514103 | E20: 9.0707917 | F20: 9.1910027 | G20: 8.3588577 | H20: 7.570896 | I20: 1.17953 | J20: 0.0013933 | K20: 0.0013933 | L20: 0.0013933 | M20: 0.0013933 | N20: 0.0013933 | O20: 0.0013933 | P20: 0.0013933
C21: Dự phòng đầu tư ngắn hạn | D21: -3.7812352 | E21: -4.828872 | F21: -5.3902039 | G21: -4.1179572 | H21: -4.1316491 | I21: -0.3057319 | J21: 0 | K21: 0 | L21: 0 | M21: 0 | N21: 0 | O21: 0 | P21: 0
C22: Đầu tư nắm giữ đến ngày đáo hạn | D22: 0 | E22: 0 | F22: 0 | G22: 0 | H22: 0 | I22: 0 | J22: 110 | K22: 274.111 | L22: 313.8 | M22: 222.7 | N22: 113.94 | O22: 93.34 | P22: 139.2
C23: Các khoản phải thu | D23: 132.69903 | E23: 254.15788 | F23: 211.96627 | G23: 212.35944 | H23: 192.18521 | I23: 276.91296 | J23: 272.48072 | K23: 372.12792 | L23: 405.93248 | M23: 428.87787 | N23: 445.14765 | O23: 412.70151 | P23: 503.84008
C24: Phải thu khách hàng | D24: 118.0936 | E24: 239.82706 | F24: 195.28014 | G24: 204.28602 | H24: 167.36503 | I24: 242.88833 | J24: 255.39416 | K24: 319.40608 | L24: 339.16997 | M24: 380.7234 | N24: 407.28591 | O24: 412.78328 | P24: 496.56441
C25: Trả trước người bán | D25: 13.488462 | E25: 13.00845 | F25: 18.408142 | G25: 17.516065 | H25: 33.439064 | I25: 41.254525 | J25: 30.333859 | K25: 57.615319 | L25: 72.424661 | M25: 54.191459 | N25: 58.587922 | O25: 37.671562 | P25: 41.540322
C26: Phải thu nội bộ | D26: 0 | E26: 0 | F26: 0 | G26: 0 | H26: 0 | I26: 0 | J26: 0 | K26: 0 | L26: 0 | M26: 0 | N26: 0 | O26: 0 | P26: 0
... C73: Lợi thế thương mại (trước 2015) | D73: 2.3078375 | E73: 1.9781464 | F73: 1.6484554 | G73: 1.3187643 | H73: 1.7203994 | I73: 0 | J73: 0 | K73: 0 | L73: 0 | M73: 0 | N73: 0 | O73: 0 | P73: 0
C74: Tài sản dài hạn khác | D74: 5.1601745 | E74: 5.5266888 | F74: 8.2865175 | G74: 6.8283502 | H74: 12.267887 | I74: 9.5248181 | J74: 3.6169953 | K74: 12.188688 | L74: 30.486433 | M74: 25.586234 | N74: 40.525556 | O74: 40.759715 | P74: 34.41005 | R74: -6.3496648
C75: Trả trước dài hạn | D75: 4.1803029 | E75: 4.2901068 | F75: 6.7187366 | G75: 4.8364252 | H75: 9.2858691 | I75: 7.8724232 | J75: 3.6169953 | K75: 12.188688 | L75: 30.486433 | M75: 25.586234 | N75: 40.417123 | O75: 40.666421 | P75: 0
C76: Thuế thu nhập hoãn lại phải thu | D76: 0.60095561 | E76: 0.42176594 | F76: 0.23461757 | G76: 0.13609603 | H76: 0.1530109 | I76: 0.33669437 | J76: 0 | K76: 0 | L76: 0 | M76: 0 | N76: 0.10843274 | O76: 0.093293942 | P76: 0
C77: Thiết bị, vật tư, phụ tùng thay thế dài hạn | D77: 0 | E77: 0 | F77: 0 | G77: 0 | H77: 0 | I77: 0 | J77: 0 | K77: 0 | L77: 0 | M77: 0 | N77: 0 | O77: 0 | P77: 0
C78: Các tài sản dài hạn khác | D78: 0.378916 | E78: 0.814816 | F78: 1.3331634 | G78: 1.855829 | H78: 2.8290071 | I78: 0 | J78: 0 | K78: 0 | L78: 0 | M78: 0 | N78: 0 | O78: 0 | P78: 0
C79: Lợi thế thương mại | D79: 0 | E79: 0 | F79: 0 | G79: 0 | H79: 0 | I79: 1.3157005 | J79: 0 | K79: 0 | L79: 0 | M79: 0 | N79: 0 | O79: 0 | P79: 0
C80: TỔNG CỘNG TÀI SẢN | D80: 488.63764 | E80: 603.07961 | F80: 626.2223 | G80: 742.90043 | H80: 920.41146 | I80: 1090.9459 | J80: 1067.9332 | K80: 1434.26 | L80: 1544.19 | M80: 1434.3409 | N80: 1620.5529 | O80: 1437.4094 | P80: 1553.4944
C81: NỢ PHẢI TRẢ | D81: 373.50485 | E81: 459.70899 | F81: 438.37542 | G81: 532.40189 | H81: 632.32325 | I81: 736.59705 | J81: 513.78854 | K81: 661.23068 | L81: 711.17977 | M81: 543.68659 | N81: 688.0446 | O81: 448.78391 | P81: 418.35302
C82: Nợ ngắn hạn | D82: 333.47711 | E82: 435.36409 | F82: 412.70041 | G82: 514.18875 | H82: 594.82196 | I82: 699.65556 | J82: 482.08875 | K82: 612.15608 | L82: 655.81064 | M82: 497.31971 | N82: 580.31211 | O82: 347.87234 | P82: 293.26127
C83: Phải trả người bán | D83: 46.46339 | E83: 54.069454 | F83: 65.016445 | G83: 75.670533 | H83: 75.345927 | I83: 85.018742 | J83: 151.67171 | K83: 249.65009 | L83: 196.24762 | M83: 204.50767 | N83: 211.39591 | O83: 102.65215 | P83: 96.81303
C84: Người mua trả tiền trước | D84: 7.9910681 | E84: 8.2572546 | F84: 8.5527674 | G84: 14.556539 | H84: 17.928537 | I84: 15.125623 | J84: 15.068433 | K84: 6.5513423 | L84: 31.13507 | M84: 14.769554 | N84: 5.1531493 | O84: 28.952275 | P84: 10.607673
C85: Thuế và các khoản phải trả Nhà nước | D85: 4.3599082 | E85: 5.7650382 | F85: 8.4025578 | G85: 13.042855 | H85: 16.245141 | I85: 12.714346 | J85: 28.588905 | K85: 23.567266 | L85: 30.183982 | M85: 9.72081 | N85: 27.98454 | O85: 18.47604 | P85: 0
C86: Phải trả người lao động | D86: 16.594478 | E86: 30.740877 | F86: 34.439871 | G86: 36.000169 | H86: 39.525746 | I86: 54.151323 | J86: 53.490475 | K86: 70.359021 | L86: 40.739387 | M86: 14.603357 | N86: 27.415983 | O86: 36.378113 | P86: 0
... C136: TỔNG CỘNG NGUỒN VỐN | D136: 488.63764 | E136: 603.07961 | F136: 626.2223 | G136: 742.90043 | H136: 920.41146 | I136: 1090.9459 | J136: 1067.9332 | K136: 1434.26 | L136: 1544.19 | M136: 1434.3409 | N136: 1620.5529 | O136: 1437.4094 | P136: 1553.4944
C138: STOXPLUS CORPORATION
C139: Trụ sở: Tầng 5, Tòa nhà Anh Minh, 36 Hoàng Cầu, Đống Đa, Hà Nội
C140: Chi nhánh TP HCM: Tầng 2 May Plaza - 63D Võ Văn Tần, Phường 6, Quận 3, TP.HCM
...

Sheet CF Raw
C5: Tiêu đề
C6: Ngày xuất dữ liệu
C8: Mã CK | D8: DBD | E8: DBD | F8: Xem theo | G8: Năm | H8: 2018
C9: Loại | D9: Hợp nhất | F9: Tiền tệ | G9: VNĐ | H9: VNĐ
J10: 308.06553
C11: Gián tiếp | D11: 2009 | E11: 2010 | F11: 2011 | G11: 2012 | H11: 2013 | I11: 2014 | J11: 2015 | K11: 2016 | L11: 2017 | M11: 2018 | N11: 2019 | O11: 2020 | P11: 2021
C12: Trạng thái kiểm toán | D12: Đã kiểm toán | E12: Đã kiểm toán | F12: Đã kiểm toán | G12: Đã kiểm toán | H12: Đã kiểm toán | I12: Đã kiểm toán | J12: Đã kiểm toán | K12: Đã kiểm toán | L12: Đã kiểm toán | M12: Đã kiểm toán | N12: Đã kiểm toán | O12: Đã kiểm toán | P12: Đã kiểm toán
C13: Công ty Kiểm toán | G13: Kiểm toán AASC | H13: Kiểm toán AASC | I13: Kiểm toán AASC | J13: Kiểm toán AASC | K13: Kiểm toán AASC | L13: Kiểm toán AASC | M13: Kiểm toán AASC | N13: Kiểm toán AASC | O13: Kiểm toán AASC | P13: Kiểm toán AASC
C14: Loại Ý kiến Kiểm toán | G14: N/A | H14: Chấp nhận toàn phần | I14: Chấp nhận toàn phần | J14: Chấp nhận toàn phần | K14: Chấp nhận toàn phần | L14: Chấp nhận toàn phần | M14: Chấp nhận toàn phần | N14: Chấp nhận toàn phần | O14: Chấp nhận toàn phần | P14: Chấp nhận toàn phần
C15: Lãi trước thuế | D15: 0 | E15: 52.579675 | F15: 73.138861 | G15: 87.27956 | H15: 128.43885 | I15: 150.14317 | J15: 273.85551 | K15: 175.88104 | L15: 203.59645 | M15: 201.02634 | N15: 174.01329 | O15: 193.19132 | P15: 0
C16: Khấu hao TSCĐ | D16: 0 | E16: 28.622377 | F16: 31.478679 | G16: 36.860873 | H16: 48.00734 | I16: 68.371455 | J16: 39.216982 | K16: 33.793831 | L16: 36.813842 | M16: 36.516915 | N16: 27.945022 | O16: 31.808991 | P16: 40.674128
C17: Phân bổ lợi thế thương mại | D17: 0 | E17: 0 | F17: 0 | G17: 0 | H17: 0 | I17: 0 | J17: 0 | K17: 0 | L17: 0 | M17: 0 | N17: 0 | O17: 0 | P17: 0
C18: Chi phí dự phòng | D18: 0 | E18: -15.692028 | F18: 2.2117206 | G18: 0.2162593 | H18: -0.43876799 | I18: -3.1254635 | J18: 25.788019 | K18: -5.1495658 | L18: -2.6443794 | M18: 1.1207052 | N18: 14.547849 | O18: 14.288447 | P18: 14.288447
C19: (Lãi)/lỗ chênh lệch tỷ giá chưa thực hiện | D19: 0 | E19: 0 | F19: 0 | G19: 0.092933761 | H19: 0.11801748 | I19: -0.59503311 | J19: -0.42643001 | K19: 0.30575327 | L19: -0.003749822 | M19: -0.089566701 | N19: 0.069131555 | O19: 0.69521357 | P19: 0
C20: (Lãi)/lỗ từ thanh lý tài sản cố định | D20: 0 | E20: 0 | F20: 0 | G20: 0 | H20: 0 | I20: 0 | J20: 0 | K20: 0 | L20: 0 | M20: 0 | N20: 0 | O20: 0 | P20: 0
C21: (Lãi)/lỗ từ hoạt động đầu tư | D21: 0 | E21: -1.1133429 | F21: -1.4633982 | G21: 3.2282626 | H21: -1.4803883 | I21: -4.5389949 | J21: -47.816327 | K21: -25.707874 | L21: -25.73558 | M21: -26.323733 | N21: -27.371186 | O21: -24.246805 | P21: -24.246805
C22: Chi phí lãi vay | D22: 0 | E22: 36.630793 | F22: 45.318451 | G22: 30.483197 | H22: 19.654885 | I22: 25.505476 | J22: 5.4477753 | K22: 4.498013 | L22: 6.8281941 | M22: 8.3658397 | N22: 10.314155 | O22: 6.5888547 | P22: 1.3245274
C23: Thu lãi và cổ tức | D23: 0 | E23: 0 | F23: 0 | G23: 0 | H23: 0 | I23: 0 | J23: 0 | K23: 0 | L23: 0 | M23: 0 | N23: 0 | O23: 0 | P23: 0
C24: Các khoản điều chỉnh khác | D24: 0 | E24: 0 | F24: 0 | G24: 0 | H24: 0 | I24: 0 | J24: 12 | K24: 17 | L24: 15 | M24: 0 | N24: -1.5017455 | O24: 0.014646581 | P24: 0
C25: Lãi/(lỗ) trước những thay đổi vốn lưu động | D25: 0 | E25: 101.02747 | F25: 150.68431 | G25: 158.16109 | H25: 194.29994 | I25: 235.76061 | J25: 308.06553 | K25: 200.6212 | L25: 233.85478 | M25: 220.61651 | N25: 198.01651 | O25: 222.34066 | P25: 0
C26: (Tăng)/giảm các khoản phải thu | D26: 0 | E26: -128.53364 | F26: 40.928178 | G26: -11.715985 | H26: 15.652325 | I26: -78.427583 | J26: 131.73249 | K26: -94.86457 | L26: -27.298478 | M26: -9.0717265 | N26: -58.92951 | O26: 29.325194 | P26: -84.79
... C55: Tiền và tương đương tiền cuối kỳ | D55: 21.196006 | E55: 44.016582 | F55: 36.96126 | G55: 98.834989 | H55: 100.57208 | I55: 127.49809 | J55: 210.69177 | K55: 135.54888 | L55: 96.499799 | M55: 92.556725 | N55: 138.16218 | O55: 108.72871 | P55: 0
C57: STOXPLUS CORPORATION
C58: Trụ sở: Tầng 5, Tòa nhà Anh Minh, 36 Hoàng Cầu, Đống Đa, Hà Nội
C59: Chi nhánh TP HCM: Tầng 2 May Plaza - 63D Võ Văn Tần, Phường 6, Quận 3, TP.HCM
C60: Email: Stoxplus@StoxPlus.com
C62: TRUNG TÂM CHĂM SÓC KHÁCH HÀNG
C63: Tại Hà Nội
C64: Ms. Đỗ Thị Lan - chuyên viên chăm sóc Khách hàng
C65: T: (844) - 3562 6962 - Ext: 103 M: 0989 219 401
C66: Email: lan.do@StoxPlus.com
C68: Tại HCM
C69: Ms. Lý Thị Hiền - Chuyên viên chăm sóc Khách hàng
C70: T: (848)- 3933 3586 - ext: 201 M: 0942863986
C71: Email: hien.ly@stoxplus.com

Sheet Notes
C5: Tiêu đề
C6: Ngày xuất dữ liệu | H6: 1000000000 | P6: 1000000000
C8: Mã CK | D8: DBD | F8: Xem theo | G8: Năm | H8: 2018
C9: Loại | D9: Hợp nhất | F9: Tiền tệ | G9: VNĐ | H9: VNĐ
D11: 2009 | E11: 2010 | F11: 2011 | G11: 2012 | H11: 2013 | I11: 2014 | J11: 2015 | K11: 2016 | L11: 2017 | M11: 2018 | N11: 2019 | O11: 2020 | P11: 2021
C12: Trạng thái kiểm toán | D12: Đã kiểm toán | E12: Đã kiểm toán | F12: Đã kiểm toán | G12: Đã kiểm toán | H12: Đã kiểm toán | I12: Đã kiểm toán | J12: Đã kiểm toán | K12: Đã kiểm toán | L12: Đã kiểm toán | M12: Đã kiểm toán | N12: Đã kiểm toán | O12: Đã kiểm toán | P12: Đã kiểm toán
C13: Công ty Kiểm toán | G13: Kiểm toán AASC | H13: Kiểm toán AASC | I13: Kiểm toán AASC | J13: Kiểm toán AASC | K13: Kiểm toán AASC | L13: Kiểm toán AASC | M13: Kiểm toán AASC | N13: Kiểm toán AASC | O13: Kiểm toán AASC | P13: Kiểm toán AASC
C14: Loại Ý kiến Kiểm toán | G14: N/A | H14: Chấp nhận toàn phần | I14: Chấp nhận toàn phần | J14: Chấp nhận toàn phần | K14: Chấp nhận toàn phần | L14: Chấp nhận toàn phần | M14: Chấp nhận toàn phần | N14: Chấp nhận toàn phần | O14: Chấp nhận toàn phần | P14: Chấp nhận toàn phần
C15: Tiền | D15: 21.196006 | E15: 44.016582 | F15: 36.96126 | G15: 98.834989 | H15: 100.57208 | I15: 127.49809 | J15: 210.7 | K15: 135.54888 | L15: 96.499799 | M15: 92.556725 | N15: 138.16218 | O15: 110.52871 | P15: 0
C16: Tiền mặt | D16: 1.9636838 | E16: 1.7728805 | F16: 4.0392071 | G16: 1.1286801 | H16: 6.0291765 | I16: 3.7866959 | J16: 0.87 | K16: 0.98680987 | L16: 0.6614968 | M16: 0.56186445 | N16: 0.7090141 | O16: 0.47311068 | P16: 0
C17: Tiền gửi Ngân hàng | D17: 19.232323 | E17: 42.243702 | F17: 32.922053 | G17: 46.17342 | H17: 94.5429 | I17: 51.140107 | J17: 52.8 | K17: 62.062072 | L17: 53.338302 | M17: 79.994861 | N17: 46.733319 | O17: 34.71156 | P17: 0
C18: Tiền đang chuyển | D18: 0 | E18: 0 | F18: 0 | G18: 0 | H18: 0 | I18: 1.445 | J18: 0 | K18: 0 | L18: 0 | M18: 0 | N18: 0 | O18: 0 | P18: 0
C19: Tiền và tương đương tiền | D19: 0 | E19: 0 | F19: 0 | G19: 51.53289 | H19: 0 | I19: 71.126283 | J19: 157 | K19: 72.5 | L19: 42.5 | M19: 12 | N19: 90.719845 | O19: 75.344044 | P19: 0
C20: Đầu tư tài chính NH | D20: 4.2701751 | E20: 4.2419197 | F20: 3.8007988 | G20: 4.2409005 | H20: 3.4392469 | I20: 0.8737981 | J20: 110 | K20: 274.11239 | L20: 313.80139 | M20: 222.70279 | N20: 113.94139 | O20: 93.341393 | P20: 0
C21: Chứng khoán đầu tư ngắn hạn | D21: 8.0514103 | E21: 9.0707917 | F21: 9.1910027 | G21: 7.570896 | H21: 7.570896 | I21: 1.17953 | J21: 0 | K21: 0.0013933 | L21: 0.0013933 | M21: 0.0013933 | N21: 0.0013933 | O21: 0.0013933 | P21: 0
C22: Đầu tư nắm giữ đến ngày đáo hạn | D22: 0 | E22: 0 | F22: 0 | G22: 0 | H22: 0 | I22: 0 | J22: 110 | K22: 274.111 | L22: 313.8 | M22: 222.70139 | N22: 113.94 | O22: 93.34 | P22: 0
C23: Ngắn hạn | D23: 0 | E23: 0 | F23: 0 | G23: 0 | H23: 0 | I23: 0 | J23: 110 | K23: 274.111 | L23: 313.8 | M23: 222.70139 | N23: 113.94 | O23: 93.34 | P23: 0
C24: Dài hạn | D24: 0 | E24: 0 | F24: 0 | G24: 0 | H24: 0 | I24: 0 | J24: 0 | K24: 0 | L24: 0 | M24: 0 | N24: 0 | O24: 0 | P24: 0
C25: Đầu tư NH khác | D25: -3.7812352 | E25: 0 | F25: 0 | G25: 0.7879617 | H25: 0 | I25: 0 | J25: 0 | K25: 0 | L25: 0 | M25: 0 | N25: 0 | O25: 0 | P25: 0
C26: Dự phòng giảm giá ĐTNH | D26: 0 | E26: -4.828872 | F26: -5.3902039 | G26: -4.1179572 | H26: -4.1316491 | I26: -0.3057319 | J26: 0 | K26: 0 | L26: 0 | M26: 0 | N26: 0 | O26: 0 | P26: 0
... C171: Chi phí khác bằng tiền | D171: 0 | E171: 0 | F171: 18.64346 | G171: 27.323059 | H171: 24.694254 | I171: 41.795572 | J171: 126.54904 | K171: 91.579131 | L171: 86.204506 | M171: 64.881516 | N171: 59.755824 | O171: 66.566996 | P171: 74.032369
C172: (Hoàn nhập)/Dự phòng phải thu khó đòi | J172: 18.695516 | K172: -4.8780667 | L172: -2.6443794 | M172: 1.1207052 | N172: 21.921386 | O172: 14.288447 | P172: 22.229182

Sheet Welfare & Dividends
B1: =1 -> 1 | K1: Số liệu 2021 chưa có vì chưa tổ chức ĐHCĐTN 2022, sử dụng số kế hoạch của ĐHCĐTN 2021 | Q1: 1 | R1: 2 | S1: 3 | T1: 4 | U1: 5 | V1: 6 | W1: 7 | X1: 8 | Y1: 9 | Z1: 10
N2: =IF(TODAY()<N3,"Proj","") | O2: =IF(TODAY()<O3,"Proj","") | P2: =IF(TODAY()<P3,"Proj","") | Q2: =IF(TODAY()<Q3,"Proj","") | R2: =IF(TODAY()<R3,"Proj","") | S2: =IF(TODAY()<S3,"Proj","") | T2: =IF(TODAY()<T3,"Proj","") -> Proj | U2: =IF(TODAY()<U3,"Proj","") -> Proj | ... Z2: =IF(TODAY()<Z3,"Proj","") -> Proj
B3: WELFARE & DIVIDENDS | D3: 40178 | E3: =DATE(YEAR(D3),MONTH(D3)+13,0) -> 40543 | F3: =DATE(YEAR(E3),MONTH(E3)+13,0) -> 40908 | G3: =DATE(YEAR(F3),MONTH(F3)+13,0) -> 41274 | H3: =DATE(YEAR(G3),MONTH(G3)+13,0) -> 41639 | I3: =DATE(YEAR(H3),MONTH(H3)+13,0) -> 42004 | J3: =DATE(YEAR(I3),MONTH(I3)+13,0) -> 42369 | K3: =DATE(YEAR(J3),MONTH(J3)+13,0) -> 42735 | L3: =DATE(YEAR(K3),MONTH(K3)+13,0) -> 43100 | ... Z3: =DATE(YEAR(Y3),MONTH(Y3)+13,0) -> 48213
A4: 1 | B4: LNST | J4: =Input!J94 -> 214.7655 | K4: =Input!K94 -> 141.49154 | L4: =Input!L94 -> 164.39079 | M4: =Input!M94 -> 163.0048 | N4: =Input!N94 -> 142.22742 | O4: =Input!O94 -> 157.85956 | P4: =Input!P94 -> 184.39928
A5: 2 | B5: Trích lập các quỹ | J5: =J6+J8 -> 51.4 | K5: =K6+K8 -> 32.8 | L5: =L6+L8 -> 37.779412 | M5: =M6+M8 -> 39.121156 | N5: =N6+N8 -> 31.290032 | O5: =O6+O8 -> 34.729104 | P5: =P6+P8 -> 44.255826
A6: 2.1 | B6: Quỹ thuộc công ty | J6: =J7 -> 21.4 | K6: =K7 -> 13.7 | L6: =L7 -> 15.741422 | M6: =M7 -> 16.300481 | N6: =N7 -> 14.222742 | O6: =O7 -> 15.785956 | P6: =P7 -> 18.439928
B7: + Quỹ ĐTPT | J7: 21.4 | K7: 13.7 | L7: =15741421589/10^9 -> 15.741422 | M7: =16300481470/10^9 -> 16.300481 | N7: =14222741724/10^9 -> 14.222742 | O7: =15785956482/10^9 -> 15.785956 | P7: =0.1*P4 -> 18.439928
A8: 2.2 | B8: Quỹ chi ra | I8: =J8 -> 30 | J8: =SUM(J9,J10,J11) -> 30 | K8: =SUM(K9,K10,K11) -> 19.1 | L8: =SUM(L9,L10,L11) -> 22.03799 | M8: =SUM(M9,M10,M11) -> 22.820674 | N8: =SUM(N9,N10,N11) -> 17.06729 | O8: =SUM(O9,O10,O11) -> 18.943148 | P8: =SUM(P9,P10,P11) -> 25.815899
B9: + Quỹ khen thưởng phúc lợi | J9: 21.4 | K9: 13.7 | L9: =15741421589/10^9 -> 15.741422 | M9: =16300481470/10^9 -> 16.300481 | N9: =14222741724/10^9 -> 14.222742 | O9: =15785956482/10^9 -> 15.785956 | P9: =0.1*P4 -> 18.439928
B10: + Quỹ khen thưởng BLĐ, HĐQT, BKS | J10: =4.3+4.3 -> 8.6 | K10: =2.7*2 -> 5.4 | L10: =3148284318*2/10^9 -> 6.2965686 | M10: =3260096296*2/10^9 -> 6.5201926 | N10: =1422274172/10^9*2 -> 2.8445483 | O10: =1578595648*2/10^9 -> 3.1571913 | P10: =0.02*2*P4 -> 7.375971
B11: + Quỹ khác | J11: 0 | K11: 0 | L11: 0 | M11: 0 | N11: 0 | O11: 0 | P11: 0
A12: 3 | B12: Chi cổ tức | I12: =J12 -> 62.8 | J12: =J13+J15 -> 62.8 | K12: =K13+K15 -> 78.6 | L12: =L13+L15 -> 78.5685 | M12: =M13+M15 -> 78.568372 | N12: =N13+N15 -> 78.5685 | O12: =O13+O15 -> 78.5685 | P12: =P13+P15 -> 0.466
B13: - Lần 1 | J13: 62.8 | K13: 78.6 | L13: =78568500000/10^9 -> 78.5685 | M13: =78568372500/10^9 -> 78.568372 | N13: =78568500000/10^9 -> 78.5685 | O13: =78568500000/10^9 -> 78.5685 | P13: 0.466
B14: % mệnh giá
B15: - Lần 2 | J15: 0 | K15: 0 | L15: 0 | M15: 0
B16: % mệnh giá
B17: LNST CPP | J17: =J4-J5-J12 -> 100.5655 | K17: =K4-K5-K12 -> 30.091538 | L17: =L4-L5-L12 -> 48.042882 | M17: =M4-M5-M12 -> 45.31527 | N17: =N4-N5-N12 -> 32.368885 | O17: =O4-O5-O12 -> 44.561961 | P17: =P4-P5-P12 -> 139.67745
B19: THE NUMBER OF COMMON SHARE (triệu CP)
A20: 1 | B20: SLCP phát hành đầu năm
A21: 2 | B21: Cổ tức bằng cổ phiếu
A22: 3 | B22: Cổ phiếu thưởng
A23: 4 | B23: Phát hành riêng lẻ/ công khai
B24: - đợt 1
B25: - đợt 2
A26: 5 | B26: ESOP
A27: 6 | B27: SLCP phát hành cuối năm | I27: =41918279 -> 41918279 | J27: =41918279 -> 41918279 | K27: =52379000 -> 52379000 | L27: =52379000 -> 52379000 | M27: =52379000 -> 52379000 | N27: =52379000 -> 52379000 | O27: =52379000 -> 52379000 | P27: =57612444 -> 57612444
A28: 7 | B28: CP quỹ | I28: 71 | J28: 71 | K28: 71 | L28: 85 | M28: 85 | N28: 85 | O28: 40085 | P28: 40085
A29: 8 | B29: SLCP lưu hành | I29: =I27-I28 -> 41918208 | J29: =J27-J28 -> 41918208 | K29: =K27-K28 -> 52378929 | L29: =L27-L28 -> 52378915 | M29: =M27-M28 -> 52378915 | N29: =N27-N28 -> 52378915 | O29: =O27-O28 -> 52338915 | P29: =P27-P28 -> 57572359

Sheet Phân loại dược phẩm
A3: Column1 | B3: Column2 | C3: Thuốc kháng sinh | D3: Column3 | E3: Column4 | F3: Column5 | G3: Column6 | H3: Xưởng | I3: ĐVT | J3: Ngày kê khai | K3: Giá kê khai | L3: Giá đấu thầu | M3: Chênh lệch giữa giá kê khai và giá đấu thầu | N3: Phần trăm chênh lệch | O3: Giá ước lượng | P3: Giá dùng làm cơ sở dự phóng
A4: STT | B4: Tên thuốc | C4: Hoạt chất | D4: Dạng thuốc | E4: Nhóm kháng sinh | F4: Beta Lactam | G4: Non Beta Lactam
A5: 1 | B5: BIDINAM | C5: Imipenem monohydrat | D5: Thuốc bột pha tiêm - Lỏng | E5: Carbapenems | F5: x | H5: (7) | I5: Lọ | J5: 44582 | K5: 103000 | L5: 51660 | M5: =K5-L5 -> 51340 | N5: =M5/K5 -> 0.4984466 | O5: =AVERAGE(K5,L5) -> 77330 | P5: =O5*1.2 -> 92796
A6: 2 | B6: Bicebid 200 H/20 | C6: Cefixim | D6: Viên nang cứng - Rắn | E6: Cephalosporins - 3rd | F6: x | H6: (3) | I6: Viên | J6: 42926 | K6: 4200 | L6: 1069 | M6: =K6-L6 -> 3131 | N6: =M6/K6 -> 0.74547619 | O6: =AVERAGE(K6,L6) -> 2634.5 | P6: =O6*1.2 -> 3161.4
A7: 3 | B7: Bicebid 100 | C7: Cefixim | D7: Viên nang cứng - Rắn | E7: Cephalosporins - 3rd | F7: x | H7: (3) | I7: Viên | J7: 42486 | K7: 2520 | L7: 750 | M7: =K7-L7 -> 1770 | N7: =M7/K7 -> 0.70238095 | O7: =AVERAGE(K7,L7) -> 1635 | P7: =O7*1.2 -> 1962
A8: 4 | B8: Bifumax 750 H/10 | C8: Cefuroxim | D8: Thuốc bột pha tiêm - Lỏng | E8: Cephalosporins - 2nd | F8: x | H8: (7) | I8: Lọ | J8: 42604 | K8: 28400 | L8: 16989 | M8: =K8-L8 -> 11411 | N8: =M8/K8 -> 0.40179577 | O8: =AVERAGE(K8,L8) -> 22694.5 | P8: =O8*1.2 -> 27233.4
A9: 5 | B9: Colirex 1MIU | C9: Colistimethat natri | D9: Thuốc bột pha tiêm - Lỏng | E9: polypeptid - peptid | G9: x | H9: (7) | I9: Lọ | J9: 42237 | K9: 375000 | L9: 359100 | M9: =K9-L9 -> 15900 | N9: =M9/K9 -> 0.0424 | O9: =AVERAGE(K9,L9) -> 367050 | P9: =O9*1.2 -> 440460
A10: 6 | B10: VANCOMYCIN 500 mg | C10: Vancomycin | D10: Bột đông khô pha tiêm - Lỏng | E10: glycopeptid - peptid | G10: x | H10: (1) | I10: Lọ | J10: 43425 | K10: 52000 | L10: 19887 | M10: =K10-L10 -> 32113 | N10: =M10/K10 -> 0.61755769 | O10: =AVERAGE(K10,L10) -> 35943.5 | P10: =O10*1.2 -> 43132.2
A11: 7 | B11: BIFOTIN 1G | C11: Cefoxitin | D11: Thuốc bột pha tiêm - Lỏng | E11: Cephalosporins - 2nd | F11: x | H11: (7) | I11: Lọ | J11: 43209 | K11: 47250 | L11: 16695 | M11: =K11-L11 -> 30555 | N11: =M11/K11 -> 0.64666667 | O11: =AVERAGE(K11,L11) -> 31972.5 | P11: =O11*1.2 -> 38367
A12: 8 | B12: Bicefzidim 1g | C12: Ceftazidim | D12: Thuốc bột pha tiêm - Lỏng | E12: Cephalosporins - 3rd | F12: x | H12: (7) | I12: Lọ | J12: 43013 | K12: 39900 | L12: 9990 | M12: =K12-L12 -> 29910 | N12: =M12/K12 -> 0.74962406 | O12: =AVERAGE(K12,L12) -> 24945 | P12: =O12*1.2 -> 29934
A13: 9 | B13: Augbidil 500mg/62.5mg | C13: Acid clavulanic + Amoxicillin | D13: Thuốc bột pha hỗn dịch uống - Lỏng | E13: Penicillins + Beta - lactamase Inhibitors - Aminopenicillins - Phổ rộng | F13: x | H13: (6) | I13: Gói | J13: 42712 | K13: 8400 | L13: 1840 | M13: =K13-L13 -> 6560 | N13: =M13/K13 -> 0.78095238 | O13: =AVERAGE(K13,L13) -> 5120 | P13: =O13*1.2 -> 6144
A14: 10 | B14: Cefotaxone 1 g | C14: Cefotaxim | D14: Thuốc bột pha tiêm - Lỏng | E14: Cephalosporins - 3rd | F14: x | H14: (7) | I14: Lọ | J14: 42438 | K14: 15000 | L14: 5769 | M14: =K14-L14 -> 9231 | N14: =M14/K14 -> 0.6154 | O14: =AVERAGE(K14,L14) -> 10384.5 | P14: =O14*1.2 -> 12461.4
A15: 11 | B15: Bironem 1g | C15: Meropenem | D15: Thuốc bột pha tiêm - Lỏng | E15: Carbapenems | F15: x | H15: (7) | I15: Lọ | J15: 42269 | K15: 161700 | L15: 57750 | M15: =K15-L15 -> 103950 | N15: =M15/K15 -> 0.64285714 | O15: =AVERAGE(K15,L15) -> 109725 | P15: =O15*1.2 -> 131670
A16: 12 | B16: Bironem 500 mg | C16: Meropenem | D16: Thuốc bột pha tiêm - Lỏng | E16: Carbapenems | F16: x | H16: (7) | I16: Lọ | J16: 42269 | K16: 96600 | L16: 36981 | M16: =K16-L16 -> 59619 | N16: =M16/K16 -> 0.61717391 | O16: =AVERAGE(K16,L16) -> 66790.5 | P16: =O16*1.2 -> 80148.6
A17: 13 | B17: Bifumax 750 | C17: Cefuroxim | D17: Thuốc bột pha tiêm - Lỏng | E17: Cephalosporins - 2nd | F17: x | H17: (7) | I17: Lọ | J17: 42604 | K17: 28400 | L17: 16989 | M17: =K17-L17 -> 11411 | N17: =M17/K17 -> 0.40179577 | O17: =AVERAGE(K17,L17) -> 22694.5 | P17: =O17*1.2 -> 27233.4
A18: 14 | B18: Tazopelin 4,5g | C18: Piperacillin natri &Tazobactam natri | D18: Thuốc bột pha tiêm - Lỏng | E18: Penicillins + Beta - lactamase Inhibitors - Ureidopenicilin - Phổ rộng | F18: x | H18: (7) | I18: Lọ | J18: 42247 | K18: 94500 | L18: 65982 | M18: =K18-L18 -> 28518 | N18: =M18/K18 -> 0.30177778 | O18: =AVERAGE(K18,L18) -> 80241 | P18: =O18*1.2 -> 96289.2
A19: 15 | B19: Bidiclor® 125 | C19: Cefaclor | D19: Thuốc bột pha hỗn dịch uống - Lỏng | E19: Cephalosporins - 2nd | F19: x | H19: (6) | I19: Gói | J19: 43013 | K19: 3675 | L19: 1239 | M19: =K19-L19 -> 2436 | N19: =M19/K19 -> 0.66285714 | O19: =AVERAGE(K19,L19) -> 2457 | P19: =O19*1.2 -> 2948.4
A20: 16 | B20: Clyodas® 150 | C20: Clindamycin hydroclorid | D20: Viên nang cứng - Rắn | E20: lincosamid | G20: x | H20: (2) | I20: viên | J20: 43955 | K20: 1995 | L20: 735 | M20: =K20-L20 -> 1260 | N20: =M20/K20 -> 0.63157895 | O20: =AVERAGE(K20,L20) -> 1365 | P20: =O20*1.2 -> 1638
A21: 17 | B21: Bicebid 100 | C21: Cefixim | D21: Thuốc bột pha hỗn dịch uống - Lỏng | E21: Cephalosporins - 3rd | F21: x | H21: (6) | I21: Gói | J21: 43013 | K21: 3990 | L21: 1386 | M21: =K21-L21 -> 2604 | N21: =M21/K21 -> 0.65263158 | O21: =AVERAGE(K21,L21) -> 2688 | P21: =O21*1.2 -> 3225.6
A22: 18 | B22: AUGBIDIL® 250 mg/31,25 mg | C22: Acid clavulanic + Amoxicillin | D22: Thuốc bột pha hỗn dịch uống - Lỏng | E22: Penicillins + Beta - lactamase Inhibitors - Aminopenicillins - Phổ rộng | F22: x | H22: (6) | I22: Gói | J22: 42783 | K22: 5500 | L22: 1189 | M22: =K22-L22 -> 4311 | N22: =M22/K22 -> 0.78381818 | O22: =AVERAGE(K22,L22) -> 3344.5 | P22: =O22*1.2 -> 4013.4
A23: 19 | B23: CEFUBI- 100 DT | C23: Cefpodoxim | D23: Viên nén phân tán - Rắn | E23: Cephalosporins - 3rd | F23: x | H23: (3) | I23: Viên | J23: 42604 | K23: 7455 | L23: 4893 | M23: =K23-L23 -> 2562 | N23: =M23/K23 -> 0.34366197 | O23: =AVERAGE(K23,L23) -> 6174 | P23: =O23*1.2 -> 7408.8
A24: 20 | B24: Sunewtam 2g | C24: Cefoperazon natri + Sulbactam natri | D24: Thuốc bột pha tiêm - Lỏng | E24: Cephalosporins + Beta - lactamase Inhibitors - 3rd | F24: x | H24: (7) | I24: Lọ | J24: 42247 | K24: 44940 | L24: 15183 | M24: =K24-L24 -> 29757 | N24: =M24/K24 -> 0.66214953 | O24: =AVERAGE(K24,L24) -> 30061.5 | P24: =O24*1.2 -> 36073.8
A25: 21 | B25: Bifucil | C25: Levofloxacin | D25: Viên nén bao phim - Rắn | E25: Quinolon | G25: x | H25: (2) | I25: Viên | J25: 42642 | K25: 5250 | L25: 756 | M25: =K25-L25 -> 4494 | N25: =M25/K25 -> 0.856 | O25: =AVERAGE(K25,L25) -> 3003 | P25: =O25*1.2 -> 3603.6
A26: 22 | B26: Bifumax 1,5g | C26: Cefuroxim | D26: Thuốc bột pha tiêm - Lỏng | E26: Cephalosporins - 2nd | F26: x | H26: (7) | I26: Lọ | J26: 41873 | K26: 41000 | L26: 25998 | M26: =K26-L26 -> 15002 | N26: =M26/K26 -> 0.36590244 | O26: =AVERAGE(K26,L26) -> 33499 | P26: =O26*1.2 -> 40198.8
A27: 23 | B27: Bicefzidim 2 g | C27: Ceftazidim pentahydrat | D27: Thuốc bột pha tiêm - Lỏng | E27: Cephalosporins - 3rd | F27: x | H27: (7) | I27: Lọ | J27: 44490 | K27: 63000 | L27: 17997 | M27: =K27-L27 -> 45003 | N27: =M27/K27 -> 0.71433333 | O27: =AVERAGE(K27,L27) -> 40498.5 | P27: =O27*1.2 -> 48598.2
A28: 24 | B28: Biceflexin Powder | C28: Cefalexin | D28: Thuốc bột pha hỗn dịch uống - Lỏng | E28: Cephalosporins - 1st | F28: x | H28: (6) | I28: Gói | J28: 41386 | K28: 1890 | L28: 711 | M28: =K28-L28 -> 1179 | N28: =M28/K28 -> 0.62380952 | O28: =AVERAGE(K28,L28) -> 1300.5 | P28: =O28*1.2 -> 1560.6
A29: 25 | B29: Bicefdox 500 | C29: Cefadroxil | D29: Viên nang cứng - Rắn | E29: Cephalosporins - 1st | F29: x | H29: (3) | I29: viên | J29: 43914 | K29: 2940 | L29: 1743 | M29: =K29-L29 -> 1197 | N29: =M29/K29 -> 0.40714286 | O29: =AVERAGE(K29,L29) -> 2341.5 | P29: =O29*1.2 -> 2809.8
A30: 26 | B30: Clyodas 300 | C30: Clindamycin hydroclorid | D30: Viên nang cứng - Rắn | E30: lincosamid | G30: x | H30: (2) | I30: viên | J30: 43955 | K30: 3255 | L30: 1848 | M30: =K30-L30 -> 1407 | N30: =M30/K30 -> 0.43225806 | O30: =AVERAGE(K30,L30) -> 2551.5 | P30: =O30*1.2 -> 3061.8
A31: 27 | B31: AUGBIDIL 1g | C31: Amoxicillin trihydrat + Potassium clavulanat | D31: Viên nén bao phim - Rắn | E31: Penicillins + Beta - lactamase Inhibitors - Aminopenicillins - Phổ rộng | F31: x | H31: (3) | I31: Viên | J31: 42926 | K31: 9450 | L31: 2370 | M31: =K31-L31 -> 7080 | N31: =M31/K31 -> 0.74920635 | O31: =AVERAGE(K31,L31) -> 5910 | P31: =O31*1.2 -> 7092
A32: 28 | B32: Micbibleucin | C32: Cloramphenicol + Xanh methylen | D32: Viên nén bao đường - Rắn | E32: phenicol | G32: x | H32: (2) | I32: viên | J32: 43955 | K32: 1155 | L32: 520 | M32: =K32-L32 -> 635 | N32: =M32/K32 -> 0.54978355 | O32: =AVERAGE(K32,L32) -> 837.5 | P32: =O32*1.2 -> 1005
A33: 29 | B33: BIDICLOR 500 | C33: Cefaclor | D33: Viên nang cứng - Rắn | E33: Cephalosporins - 2nd | F33: x | H33: (3) | I33: Viên | J33: 42247 | K33: 8400 | L33: 4977 | M33: =K33-L33 -> 3423 | N33: =M33/K33 -> 0.4075 | O33: =AVERAGE(K33,L33) -> 6688.5 | P33: =O33*1.2 -> 8026.2
A34: 30 | B34: BIFUMAX 125 | C34: Cefuroxim axetil | D34: Thuốc cốm - Rắn | E34: Cephalosporins - 2nd | F34: x | H34: (6) | I34: Gói | J34: 41408 | K34: 6825 | L34: 2268 | M34: =K34-L34 -> 4557 | N34: =M34/K34 -> 0.66769231 | O34: =AVERAGE(K34,L34) -> 4546.5 | P34: =O34*1.2 -> 5455.8
A35: 31 | B35: SPOBAVAS 3 MIU | C35: Spiramycin | D35: Viên nén bao phim - Rắn | E35: macrolid | G35: x | H35: (2) | I35: viên | J35: 44551 | K35: 7140 | L35: 3192 | M35: =K35-L35 -> 3948 | N35: =M35/K35 -> 0.55294118 | O35: =AVERAGE(K35,L35) -> 5166 | P35: =O35*1.2 -> 6199.2
A36: 32 | B36: SPOBAVAS 1,5 MIU | C36: Spiramycin | D36: Viên nén bao phim - Rắn | E36: macrolid | G36: x | H36: (2) | I36: viên | J36: 44551 | K36: 3885 | L36: 3885 | M36: =K36-L36 -> 0 | N36: =M36/K36 -> 0 | O36: =AVERAGE(K36,L36) -> 3885 | P36: =O36*1.2 -> 4662
A37: 33 | B37: Metronidazol 250mg | C37: Metronidazol | D37: Viên nén bao phim - Rắn | E37: 5-nitro-imidazol | G37: x | H37: (2) | I37: Viên | J37: 43013 | K37: 357 | L37: 168 | M37: =K37-L37 -> 189 | N37: =M37/K37 -> 0.52941176 | O37: =AVERAGE(K37,L37) -> 262.5 | P37: =O37*1.2 -> 315
A38: 34 | B38: Biceflexin 500 | C38: Cefalexin monohydrat | D38: Viên nang cứng - Rắn | E38: Cephalosporins - 1st | F38: x | H38: (3) | I38: Viên | J38: 42486 | K38: 1680 | L38: 714 | M38: =K38-L38 -> 966 | N38: =M38/K38 -> 0.575 | O38: =AVERAGE(K38,L38) -> 1197 | P38: =O38*1.2 -> 1436.4
A39: 35 | B39: Bidimoxy 500 | C39: Amoxicilin trihydrat | D39: Viên nang cứng - Rắn | E39: Penicillins - Aminopenicillin - Phổ rộng | F39: x | H39: (3) | I39: Viên | J39: 42388 | K39: 1365 | L39: 680 | M39: =K39-L39 -> 685 | N39: =M39/K39 -> 0.5018315 | O39: =AVERAGE(K39,L39) -> 1022.5 | P39: =O39*1.2 -> 1227
A40: 36 | B40: Bifotirin 1g | C40: Cefotiam hydroclorid | D40: Thuốc bột pha tiêm - Lỏng | E40: Cephalosporins - 2nd | F40: x | H40: (7) | I40: Lọ | J40: 41653 | K40: 84000 | L40: 27489 | M40: =K40-L40 -> 56511 | N40: =M40/K40 -> 0.67275 | O40: =AVERAGE(K40,L40) -> 55744.5 | P40: =O40*1.2 -> 66893.4
A41: 37 | B41: AUGBIDIL 625 | C41: Amoxicillin trihydrat + Potassium clavulanat | D41: Viên nén bao phim - Rắn | E41: Penicillins + Beta - lactamase Inhibitors - Aminopenicillins - Phổ rộng | F41: x | H41: (3) | I41: Viên | J41: 43013 | K41: 6825 | L41: 1848 | M41: =K41-L41 -> 4977 | N41: =M41/K41 -> 0.72923077 | O41: =AVERAGE(K41,L41) -> 4336.5 | P41: =O41*1.2 -> 5203.8
A42: 38 | B42: Bipisyn | C42: Ampicilin natri + Sulbactam natri | D42: Thuốc bột pha tiêm - Lỏng | E42: Penicillins + Beta - lactamase Inhibitors - Aminopenicillins - Phổ rộng | F42: x | H42: (7) | I42: Lọ | J42: 42395 | K42: 42000 | L42: 21987 | M42: =K42-L42 -> 20013 | N42: =M42/K42 -> 0.4765 | O42: =AVERAGE(K42,L42) -> 31993.5 | P42: =O42*1.2 -> 38392.2
...

Sheet Mảng dược phẩm
Q1: 1 | R1: 2 | S1: 3 | T1: 4 | U1: 5 | V1: 6 | W1: 7 | X1: 8 | Y1: 9 | Z1: 10 | AA1: 11 | AB1: 12 | AC1: 13 | AD1: 14 | AE1: 15 | AF1: 16 | AG1: 17 | AH1: 18 | AI1: 19 | AJ1: 20 | AK1: 21 | AL1: 22 | AM1: 23 | AN1: 24 | AO1: 25 | AP1: 26 | AQ1: 27 | AR1: 28 | AS1: 29 | AT1: 30 | AU1: 31 | AV1: 32 | AW1: 33 | AX1: 34 | AY1: 35 | AZ1: 36 | BA1: 37 | BB1: 38 | BC1: 39 | BD1: 40
E2: =IF(TODAY()<E3,"Proj","") | F2: =IF(TODAY()<F3,"Proj","") | I2: =IF(TODAY()<I3,"Proj","") | J2: =IF(TODAY()<J3,"Proj","") | K2: =IF(TODAY()<K3,"Proj","") | L2: =IF(TODAY()<L3,"Proj","") | M2: =IF(TODAY()<M3,"Proj","") | N2: =IF(TODAY()<N3,"Proj","") | O2: =IF(TODAY()<O3,"Proj","") | P2: =IF(TODAY()<P3,"Proj","") | ... BD2: =IF(TODAY()<BD3,"Proj","") -> Proj
F3: 39813 | G3: =DATE(YEAR(F3),MONTH(F3)+13,0) -> 40178 | H3: =DATE(YEAR(G3),MONTH(G3)+13,0) -> 40543 | I3: =DATE(YEAR(H3),MONTH(H3)+13,0) -> 40908 | J3: =DATE(YEAR(I3),MONTH(I3)+13,0) -> 41274 | K3: =DATE(YEAR(J3),MONTH(J3)+13,0) -> 41639 | L3: =DATE(YEAR(K3),MONTH(K3)+13,0) -> 42004 | M3: =DATE(YEAR(L3),MONTH(L3)+13,0) -> 42369 | N3: =DATE(YEAR(M3),MONTH(M3)+13,0) -> 42735 | ... BD3: =DATE(YEAR(BC3),MONTH(BC3)+13,0) -> 58075
B6: REVENUE (price - sale - volume)
A8: 1 | B8: DOANH THU (1.000 tỷ đồng)
B9: Xưởng sản xuất thuốc đông khô – sản phẩm vô trùng | C9: (1) | D9: GMP-WHO | R9: =R192*R219/1000 -> 2819.1864 | S9: =S192*S219/1000 -> 2819.1864 | T9: =T192*T219/1000 -> 2905.4881 | U9: =U192*U219/1000 -> 2934.5429 | V9: =V192*V219/1000 -> 2963.8884 | W9: =W192*W219/1000 -> 2993.5273 | X9: =X192*X219/1000 -> 3023.4625 | Y9: =Y192*Y219/1000 -> 3053.6972 | ... AD9: =AD192*AD219/1000 -> 3209.4664
B10: Xưởng sản xuất thuốc viên (Non – Betalactam); | C10: (2) | D10: GMP-WHO | R10: =R193*R220/1000 -> 196.99242 | S10: =S193*S220/1000 -> 196.99242 | T10: =T193*T220/1000 -> 203.0228 | U10: =U193*U220/1000 -> 205.05303 | V10: =V193*V220/1000 -> 207.10356 | W10: =W193*W220/1000 -> 209.1746 | X10: =X193*X220/1000 -> 211.26634 | Y10: =Y193*Y220/1000 -> 213.37901 | ... AD10: =AD193*AD220/1000 -> 224.26348
B11: Xưởng sản xuất thuốc viên (Betalactam) | C11: (3) | D11: GMP-WHO | R11: =R194*R221/1000 -> 184.35803 | S11: =S194*S221/1000 -> 184.35803 | T11: =T194*T221/1000 -> 190.00164 | U11: =U194*U221/1000 -> 191.90166 | V11: =V194*V221/1000 -> 193.82067 | W11: =W194*W221/1000 -> 195.75888 | X11: =X194*X221/1000 -> 197.71647 | Y11: =Y194*Y221/1000 -> 199.69364 | ... AD11: =AD194*AD221/1000 -> 209.88002
B12: Xưởng sản xuất thuốc viên nang mềm - thuốc đạn | C12: (4) | D12: GMP-WHO | R12: =R195*R222/1000 -> 69.323517 | S12: =S195*S222/1000 -> 69.323517 | T12: =T195*T222/1000 -> 70.738282 | U12: =U195*U222/1000 -> 70.738282 | V12: =V195*V222/1000 -> 70.738282 | W12: =W195*W222/1000 -> 70.738282 | X12: =X195*X222/1000 -> 70.738282 | Y12: =Y195*Y222/1000 -> 70.738282 | ... AD12: =AD195*AD222/1000 -> 70.738282
B13: Xưởng sản xuất thuốc kem - mỡ - nước | C13: (5) | D13: GMP-WHO | R13: =R196*R223/1000 -> 155.49374 | S13: =S196*S223/1000 -> 155.49374 | T13: =T196*T223/1000 -> 160.25375 | U13: =U196*U223/1000 -> 161.85629 | V13: =V196*V223/1000 -> 163.47485 | W13: =W196*W223/1000 -> 165.1096 | X13: =X196*X223/1000 -> 166.7607 | Y13: =Y196*Y223/1000 -> 168.4283 | ... AD13: =AD196*AD223/1000 -> 177.01984
B14: Xưởng sản xuất thuốc bột vi sinh | C14: (6) | D14: GMP-WHO | R14: =R197*R224/1000 -> 4.5474752 | S14: =S197*S224/1000 -> 4.5474752 | T14: =T197*T224/1000 -> 4.6402808 | U14: =U197*U224/1000 -> 4.6402808 | V14: =V197*V224/1000 -> 4.6402808 | W14: =W197*W224/1000 -> 4.6402808 | X14: =X197*X224/1000 -> 4.6402808 | Y14: =Y197*Y224/1000 -> 4.6402808 | ... AD14: =AD197*AD224/1000 -> 4.6402808
B15: Xưởng sản xuất thuốc tiêm bột | C15: (7) | D15: GMP-WHO | R15: =R198*R225/1000 -> 6341.6799 | S15: =S198*S225/1000 -> 6341.6799 | T15: =T198*T225/1000 -> 6600.524 | U15: =U198*U225/1000 -> 6732.5345 | V15: =V198*V225/1000 -> 6867.1852 | W15: =W198*W225/1000 -> 7004.5289 | X15: =X198*X225/1000 -> 7144.6195 | Y15: =Y198*Y225/1000 -> 7158.2986 | ... AD15: =AD198*AD225/1000 -> 7158.2986
B16: Nhà máy sản xuất dược phẩm Bidiphar Công nghệ Cao tại Công ty TNHH Bidiphar Công nghệ Cao
B17: i) Nhà máy sản xuất thuốc điều trị ung thư
B18: Thuốc viên điều trị ung thư | C18: (8) | D18: GMP-PICS/EU | S18: =S201 * S228 -> 1349.1479 | T18: =T201 * T228 -> 9623.9216 | U18: =U201 * U228 -> 10297.596 | V18: =V201 * V228 -> 35222.628 | W18: =W201 * W228 -> 40153.796 | X18: =X201 * X228 -> 45775.328 | Y18: =Y201 * Y228 -> 52183.874 | Z18: =Z201 * Z228 -> 59489.616 | ... AD18: =AD201 * AD228 -> 100475.59
B19: Thuốc tiêm điều trị ung thư | C19: (9) | D19: GMP-PICS/EU | S19: =S202 * S229 -> 252029.55 | T19: =T202 * T229 -> 1797810.8 | U19: =U202 * U229 -> 1923657.5 | V19: =V202 * V229 -> 6579814.7 | W19: =W202 * W229 -> 7500988.7 | X19: =X202 * X229 -> 8551127.1 | Y19: =Y202 * Y229 -> 9748284.9 | Z19: =Z202 * Z229 -> 11113045 | ... AD19: =AD202 * AD229 -> 18769490
B20: ii) Nhà máy sản xuất thuốc uống dạng rắn không chứa nhóm Betalactam | C20: (10) | D20: GMP-PICS/EU | T20: =T230*T203 -> 115626.76
B21: Nhà máy sản xuất dược phẩm Bidiphar Non – Betalactam tại Công ty TNHH Bidiphar Non - Betalactam
B22: Non Betalactam - Lỏng | C22: (11) | D22: GMP-WHO | T22: =T155*T205 -> 0 | U22: =U155*U205 -> 0 | V22: =V155*V205 -> 542.89 | W22: =W155*W205 -> 564.82276 | X22: =X155*X205 -> 587.6416 | Y22: =Y155*Y205 -> 611.38232 | Z22: =Z155*Z205 -> 636.08216 | AA22: =AA155*AA205 -> 661.77988 | ... AD22: =AD155*AD205 -> 745.27163
B23: Non Betalactam - Rắn | C23: (12) | D23: GMP-WHO | T23: =T156*T206 -> 0 | U23: =U156*U206 -> 0 | V23: =V156*V206 -> 278.89 | W23: =W156*W206 -> 290.15716 | X23: =X156*X206 -> 301.87951 | Y23: =Y156*Y206 -> 314.07544 | Z23: =Z156*Z206 -> 326.76408 | AA23: =AA156*AA206 -> 339.96535 | ... AD23: =AD156*AD206 -> 382.85621
B24: Nhà máy sản xuất dược phẩm Bidiphar Betalactam tại Công ty TNHH Bidiphar Betalactam
B25: Thuốc tiêm bột nhóm Cepharlosporin | C25: (13) | D25: GMP-PICS/EU | T25: =T158*T208 -> 0 | U25: =U158*U208 -> 0 | V25: =V158*V208 -> 0 | W25: =W158*W208 -> 2.25 | X25: =X158*X208 -> 2.5281 | Y25: =Y158*Y208 -> 2.8405732 | Z25: =Z158*Z208 -> 3.3132445 | AA25: =AA158*AA208 -> 3.8645684 | ... AD25: =AD158*AD208 -> 6.1325844
B26: Thuốc viên nhóm Cepharlosporin | C26: (14) | D26: GMP-WHO | T26: =T159*T209 -> 0 | U26: =U159*U209 -> 0 | V26: =V159*V209 -> 0 | W26: =W159*W209 -> 0 | X26: =X159*X209 -> 0 | Y26: =Y159*Y209 -> 0 | Z26: =Z159*Z209 -> 16 | AA26: =AA159*AA209 -> 16.9744 | ... AD26: =AD159*AD209 -> 20.268321
B27: Thuốc tiêm bột nhóm Penicillin | C27: (15) | D27: GMP-WHO | T27: =T160*T210 -> 0 | U27: =U160*U210 -> 0 | V27: =V160*V210 -> 0 | W27: =W160*W210 -> 0 | X27: =X160*X210 -> 0.2025 | Y27: =Y160*Y210 -> 0.21483225 | Z27: =Z160*Z210 -> 0.22791553 | AA27: =AA160*AA210 -> 0.24179559 | ... AD27: =AD160*AD210 -> 0.28871658
B28: Thuốc viên nhóm Penicillin | C28: (16) | D28: GMP-WHO | T28: =T161*T211 -> 0 | U28: =U161*U211 -> 0 | V28: =V161*V211 -> 0 | W28: =W161*W211 -> 0 | X28: =X161*X211 -> 0.0625 | Y28: =Y161*Y211 -> 0.06630625 | Z28: =Z161*Z211 -> 0.070344301 | AA28: =AA161*AA211 -> 0.074628269 | ... AD28: =AD161*AD211 -> 0.089110055
B29: Khác | C29: (17) | T29: =T162*T212 -> 0 | U29: =U162*U212 -> 0 | V29: =V162*V212 -> 0 | W29: =W162*W212 -> 0 | X29: =X162*X212 -> 0 | Y29: =Y162*Y212 -> 0 | Z29: =Z162*Z212 -> 0 | AA29: =AA162*AA212 -> 0 | ... AD29: =AD162*AD212 -> 0
B30: Tổng doanh thu | E30: tỷ đồng | M30: ='IS Raw'!J18 -> 1119.03 | N30: ='IS Raw'!K18 -> 1260.14 | O30: ='IS Raw'!L18 -> 1255.63 | P30: ='IS Raw'!M18 -> 1220.84 | Q30: ='IS Raw'!N18 -> 1143.14 | R30: ='IS Raw'!O18 -> 1148.3 | S30: ='IS Raw'!P18 -> 1191.05 | T30: =(T213*10^6*T240)/(10^9) -> 1508.1887 | U30: =(U213*10^6*U240)/(10^9) -> 1539.1105 | V30: =(V213*10^6*V240)/(10^9) -> 1960.4427 | W30: =(W213*10^6*W240)/(10^9) -> 2084.2085 | X30: =(X213*10^6*X240)/(10^9) -> 2217.9866 | Y30: =(Y213*10^6*Y240)/(10^9) -> 2325.2353 | Z30: =(Z213*10^6*Z240)/(10^9) -> 2461.8973 | AA30: =(AA213*10^6*AA240)/(10^9) -> 2559.6764 | ... AD30: =(AD213*10^6*AD240)/(10^9) -> 2907.9352 | AI30: =AI240*AI215/10^9 -> 0 | AJ30: =AJ240*AJ215/10^9 -> 0 | AK30: =AK240*AK215/10^9 -> 0 | AL30: =AL240*AL215/10^9 -> 0 | AM30: =AM240*AM215/10^9 -> 0 | AN30: =AN240*AN215/10^9 -> 0 | AO30: =AO240*AO215/10^9 -> 0 | AP30: =AP240*AP215/10^9 -> 0 | ... BD30: =BD240*BD215/10^9 -> 0
N32: =N30/M30-1 -> 0.12610028 | O32: =O30/N30-1 -> -0.0035789674 | P32: =P30/O30-1 -> -0.027707207 | Q32: =Q30/P30-1 -> -0.063644704 | R32: =R30/Q30-1 -> 0.0045138828 | S32: =S30/R30-1 -> 0.037228947 | T32: =T30/S30-1 -> 0.26626816 | U32: =U30/T30-1 -> 0.02050258 | ... AD32: =AD30/AC30-1 -> 0.045348036
A34: 2 | B34: Growth (1.000 tỷ đồng)
B35: Xưởng sản xuất thuốc đông khô – sản phẩm vô trùng | C35: (1) | D35: GMP-WHO
B36: Xưởng sản xuất thuốc viên (Non – Betalactam); | C36: (2) | D36: GMP-WHO
B37: Xưởng sản xuất thuốc viên (Betalactam) | C37: (3) | D37: GMP-WHO
B38: Xưởng sản xuất thuốc viên nang mềm - thuốc đạn | C38: (4) | D38: GMP-WHO
B39: Xưởng sản xuất thuốc kem - mỡ - nước | C39: (5) | D39: GMP-WHO
B40: Xưởng sản xuất thuốc bột vi sinh | C40: (6) | D40: GMP-WHO
B41: Xưởng sản xuất thuốc tiêm bột | C41: (7) | D41: GMP-WHO
B42: Nhà máy sản xuất dược phẩm Bidiphar Công nghệ Cao tại Công ty TNHH Bidiphar Công nghệ Cao
B43: i) Nhà máy sản xuất thuốc điều trị ung thư
B44: Thuốc viên điều trị ung thư | C44: (8) | D44: GMP-PICS/EU
B45: Thuốc tiêm điều trị ung thư | C45: (9) | D45: GMP-PICS/EU
...

Sheet Mảng thiết bị y tế
O1: 1 | P1: 2 | Q1: 3 | R1: 4 | S1: 5 | T1: 6 | U1: 7 | V1: 8 | W1: 9 | X1: 10 | Y1: 11 | Z1: 12 | AA1: 13 | AB1: 14 | AC1: 15 | AD1: 16 | AE1: 17 | AF1: 18 | AG1: 19 | AH1: 20 | AI1: 21 | AJ1: 22 | AK1: 23 | AL1: 24 | AM1: 25 | AN1: 26 | AO1: 27 | AP1: 28 | AQ1: 29 | AR1: 30 | AS1: 31 | AT1: 32 | AU1: 33 | AV1: 34 | AW1: 35 | AX1: 36 | AY1: 37 | AZ1: 38 | BA1: 39 | BB1: 40
Q2: Proj | R2: Proj | S2: Proj | T2: Proj | U2: Proj | V2: Proj | W2: Proj | X2: Proj | Y2: Proj | Z2: Proj | AA2: Proj | AB2: Proj | AC2: Proj | AD2: Proj | AE2: Proj | AF2: Proj | AG2: Proj | AH2: Proj | AI2: Proj | AJ2: Proj | AK2: Proj | AL2: Proj | AM2: Proj | AN2: Proj | AO2: Proj | AP2: Proj | AQ2: Proj | AR2: Proj | AS2: Proj | AT2: Proj | AU2: Proj | AV2: Proj | AW2: Proj | AX2: Proj | AY2: Proj | AZ2: Proj | BA2: Proj | BB2: Proj
D3: 40178 | E3: 40543 | F3: 40908 | G3: 41274 | H3: 41639 | I3: 42004 | J3: 42369 | K3: 42735 | L3: 43100 | M3: 43465 | N3: 43830 | O3: 44196 | P3: 44561 | Q3: 44926 | R3: 45291 | S3: 45657 | T3: 46022 | U3: 46387 | V3: 46752 | W3: 47118 | X3: 47483 | Y3: 47848 | Z3: 48213 | AA3: 48579 | AB3: 48944 | AC3: 48944 | AD3: 49309 | AE3: 49674 | AF3: 50040 | AG3: 50405 | AH3: 50770 | AI3: 51135 | AJ3: 51501 | AK3: 51866 | AL3: 52231 | AM3: 52596 | AN3: 52962 | AO3: 53327 | AP3: 53692 | AQ3: 54057 | AR3: 54423 | AS3: 54788 | AT3: 55153 | AU3: 55518 | AV3: 55884 | AW3: 56249 | AX3: 56614 | AY3: 56979 | AZ3: 57345 | BA3: 57710 | BB3: 58075
B6: REVENUE (price - sale - volume)
A8: 1 | B8: DOANH THU (tỷ đồng)
B9: Bán vật tư y tế | J9: ='IS Raw'!J19 -> 94.46 | K9: ='IS Raw'!K19 -> 115.1 | L9: ='IS Raw'!L19 -> 117.07 | M9: ='IS Raw'!M19 -> 169.49 | N9: ='IS Raw'!N19 -> 103.75 | O9: ='IS Raw'!O19 -> 92.31 | P9: ='IS Raw'!P19 -> 352.87 | Q9: =AVERAGE(AVERAGE(K9:O9), AVERAGE(K9:P9)) -> 138.98783 | R9: =Q9*(1+R14) -> 177.17952 | S9: =R9*(1+S14) -> 212.61543 | T9: =S9*(1+T14) -> 233.87697 | U9: =T9*(1+U14) -> 245.57082 | V9: =U9*(1+V14) -> 257.84936 | W9: =V9*(1+W14) -> 270.74183 | X9: =W9*(1+X14) -> 278.86408 | Y9: =X9*(1+Y14) -> 287.23001 | ... AC9: =AB9*(1+AC14) -> 313.86398 | AS9: 0 | AT9: 0 | AU9: 0 | AV9: 0 | AW9: 0 | AX9: 0 | AY9: 0 | AZ9: 0 | BA9: 0 | BB9: 0
B10: Bán nguyên liệu,bao bì, công cụ, dụng cụ, khác | J10: ='IS Raw'!J20 -> 11.65 | K10: ='IS Raw'!K20 -> 10.26 | L10: ='IS Raw'!L20 -> 15.82 | M10: ='IS Raw'!M20 -> 10.68 | N10: ='IS Raw'!N20 -> 15.12 | O10: ='IS Raw'!O20 -> 16.35 | P10: ='IS Raw'!P20 -> 14.58 | Q10: =AVERAGE(AVERAGE(K10:O10), AVERAGE(K10:P10)) -> 13.723833 | R10: =Q10*(1+R15) -> 15.386689 | S10: =R10*(1+S15) -> 16.309891 | T10: =S10*(1+T15) -> 17.288484 | U10: =T10*(1+U15) -> 18.325793 | V10: =U10*(1+V15) -> 19.425341 | W10: =V10*(1+W15) -> 20.590861 | X10: =W10*(1+X15) -> 21.208587 | Y10: =X10*(1+Y15) -> 21.844845 | ... AB10: =AA10*(1+AB15) -> 23.870452 | AS10: 0 | AT10: 0 | AU10: 0 | AV10: 0 | AW10: 0 | AX10: 0 | AY10: 0 | AZ10: 0 | BA10: 0 | BB10: 0
B11: Tổng | J11: =J9+J10 -> 106.11 | K11: =K9+K10 -> 125.36 | L11: =L9+L10 -> 132.89 | M11: =M9+M10 -> 180.17 | N11: =N9+N10 -> 118.87 | O11: =O9+O10 -> 108.66 | P11: =P9+P10 -> 367.45 | Q11: =Q9+Q10 -> 152.71167 | ... AB11: =AB9+AB10 -> 337.73444 | AS11: 0 | AT11: 0 | AU11: 0 | AV11: 0 | AW11: 0 | AX11: 0 | AY11: 0 | AZ11: 0 | BA11: 0 | BB11: 0
A13: 2 | B13: Growth (1.000 tỷ đồng)
B14: Bán vật tư y tế | L14: =L9/K9-1 -> 0.017115552 | M14: =M9/L9-1 -> 0.44776629 | N14: =N9/M9-1 -> -0.38786949 | O14: =O9/N9-1 -> -0.11026506 | P14: =P9/O9-1 -> 2.8226628 | Q14: =Q9/P9-1 -> -0.60612171 | R14: =AVERAGE(AVERAGE(L14:O14), AVERAGE(L14:P14)) -> 0.27478442 | S14: 0.2 | T14: =S14/2 -> 0.1 | U14: =T14/2 -> 0.05 | V14: =U14 -> 0.05 | W14: =V14 -> 0.05 | X14: 0.03 | Y14: =X14 -> 0.03 | Z14: =Y14 -> 0.03 | AA14: =Z14 -> 0.03 | AB14: =AA14 -> 0.03 | AS14: 0 | AT14: 0 | AU14: 0 | AV14: 0 | AW14: 0 | AX14: 0 | AY14: 0 | AZ14: 0 | BA14: 0 | BB14: 0
B15: Bán nguyên liệu,bao bì, công cụ, dụng cụ,khác | L15: =L10/K10-1 -> 0.54191033 | M15: =M10/L10-1 -> -0.32490518 | N15: =N10/M10-1 -> 0.41573034 | O15: =O10/N10-1 -> 0.081349206 | P15: =P10/O10-1 -> -0.10825688 | Q15: =Q10/P10-1 -> -0.058721994 | R15: =AVERAGE(L15:P15) -> 0.12116556 | S15: 0.06 | T15: =S15 -> 0.06 | U15: =T15 -> 0.06 | V15: =U15 -> 0.06 | W15: =V15 -> 0.06 | X15: =W15/2 -> 0.03 | Y15: =X15 -> 0.03 | Z15: =Y15 -> 0.03 | AA15: =Z15 -> 0.03 | AB15: =AA15 -> 0.03 | AC15: =AB15/2 -> 0.015 | AD15: =AC15/2 -> 0.0075 | AE15: =AD15/2 -> 0.00375 | AF15: =AE15/2 -> 0.001875 | AG15: =AF15/2 -> 0.0009375 | AH15: =AG15/2 -> 0.00046875 | AI15: =AH15/2 -> 0.000234375 | AJ15: =AI15/2 -> 0.0001171875 | ... BB15: =BA15/2 -> 4.4703484e-10
B16: Growth | L16: =L11/K11-1 -> 0.060067007 | M16: =M11/L11-1 -> 0.35578298 | N16: =N11/M11-1 -> -0.34023422 | O16: =O11/N11-1 -> -0.085892151 | P16: =P11/O11-1 -> 2.3816492 | Q16: =Q11/P11-1 -> -0.58440151 | R16: =R11/Q11-1 -> 0.26097906 | S16: =S11/R11-1 -> 0.18881353 | ... BB16: =BB11/BA11-1 -> #DIV/0!
A19: 3 | B19: Giá bán trung bình (vnđ/sp)
B20: Bán vật tư y tế | AE20: 0 | AF20: 0 | AG20: 0 | AH20: 0 | AI20: 0 | AJ20: 0 | AK20: 0 | AL20: 0 | AM20: 0 | AN20: 0 | AO20: 0 | AP20: 0 | AQ20: 0 | AR20: 0 | AS20: 0 | AT20: 0 | AU20: 0 | AV20: 0 | AW20: 0 | AX20: 0 | AY20: 0 | AZ20: 0 | BA20: 0 | BB20: 0
B21: Bán nguyên liệu,bao bì, công cụ, dụng cụ,khác
B22: Tổng
A24: 4 | B24: Tăng trưởng giá bán
B25: Bán vật tư y tế
B26: Bán nguyên liệu,bao bì, công cụ, dụng cụ,khác
B27: Tổng
B30: GVHB
A32: 1 | B32: GVHB
B33: Bán vật tư y tế | J33: ='IS Raw'!J23 -> 88.907278 | K33: ='IS Raw'!K23 -> 108.55258 | L33: ='IS Raw'!L23 -> 113.70558 | M33: ='IS Raw'!M23 -> 179.61155 | N33: ='IS Raw'!N23 -> 104.47008 | O33: ='IS Raw'!O23 -> 83.476642 | P33: ='IS Raw'!P23 -> 323.75084 | Q33: =Q9-Q51 -> 133.90561 | R33: =R9-R51 -> 170.70078 | S33: =S9-S51 -> 204.84094 | T33: =T9-T51 -> 225.32503 | U33: =U9-U51 -> 236.59128 | V33: =V9-V51 -> 248.42084 | W33: =W9-W51 -> 260.84189 | X33: =X9-X51 -> 268.66714 | ... BB33: =BB9-BB51 -> 0
B34: Bán nguyên liệu,bao bì, công cụ, dụng cụ,khác | J34: ='IS Raw'!J24 -> 9.7459408 | K34: ='IS Raw'!K24 -> 13.851407 | L34: ='IS Raw'!L24 -> 16.553434 | M34: ='IS Raw'!M24 -> 10.963883 | N34: ='IS Raw'!N24 -> 13.8904 | O34: ='IS Raw'!O24 -> 13.015024 | P34: ='IS Raw'!P24 -> 14.315668 | Q34: =Q10-Q52 -> 13.637798 | R34: =R10-R52 -> 15.290229 | S34: =S10-S52 -> 16.207643 | T34: =T10-T52 -> 17.180101 | U34: =U10-U52 -> 18.210907 | V34: =V10-V52 -> 19.303562 | W34: =W10-W52 -> 20.461776 | X34: =X10-X52 -> 21.075629 | ... AC34: =AC10-AC52 -> 0 | AD34: 0 | AE34: 0 | AF34: 0 | AG34: 0 | AH34: 0 | AI34: 0 | AJ34: 0 | AK34: 0 | AL34: 0 | AM34: 0 | AN34: 0 | AO34: 0 | AP34: 0 | AQ34: 0 | AR34: 0 | AS34: 0 | AT34: 0 | AU34: 0 | AV34: 0 | AW34: 0 | AX34: 0 | AY34: 0 | AZ34: 0 | BA34: 0 | BB34: 0
B35: Tổng | J35: =J33+J34 -> 98.653218 | K35: =K33+K34 -> 122.40399 | L35: =L33+L34 -> 130.25902 | M35: =M33+M34 -> 190.57543 | N35: =N33+N34 -> 118.36048 | O35: =O33+O34 -> 96.491666 | P35: =P33+P34 -> 338.06651 | Q35: =Q33+Q34 -> 147.5434 | ... BB35: =BB33+BB34 -> 0
B36: % As Revenue
A38: 2 | B38: GVHB 01 đơn vị sp
B39: Bán vật tư y tế | AC39: 0 | AD39: 0 | AE39: 0 | AF39: 0 | AG39: 0 | AH39: 0 | AI39: 0 | AJ39: 0 | AK39: 0 | AL39: 0 | AM39: 0 | AN39: 0 | AO39: 0 | AP39: 0 | AQ39: 0 | AR39: 0 | AS39: 0 | AT39: 0 | AU39: 0 | AV39: 0 | AW39: 0 | AX39: 0 | AY39: 0 | AZ39: 0 | BA39: 0 | BB39: 0
B40: Bán nguyên liệu,bao bì, công cụ, dụng cụ,khác
B41: Tổng
A43: 3 | B43: Tăng trưởng giá vốn (1.000vnđ/m3)
B44: Bán vật tư y tế | AC44: 0 | AD44: 0 | AE44: 0 | AF44: 0 | AG44: 0 | AH44: 0 | AI44: 0 | AJ44: 0 | AK44: 0 | AL44: 0 | AM44: 0 | AN44: 0 | AO44: 0 | AP44: 0 | AQ44: 0 | AR44: 0 | AS44: 0 | AT44: 0 | AU44: 0 | AV44: 0 | AW44: 0 | AX44: 0 | AY44: 0 | AZ44: 0 | BA44: 0 | BB44: 0
B45: Bán nguyên liệu,bao bì, công cụ, dụng cụ,khác | AC45: 0 | AD45: 0 | AE45: 0 | AF45: 0 | AG45: 0 | AH45: 0 | AI45: 0 | AJ45: 0 | AK45: 0 | AL45: 0 | AM45: 0 | AN45: 0 | AO45: 0 | AP45: 0 | AQ45: 0 | AR45: 0 | AS45: 0 | AT45: 0 | AU45: 0 | AV45: 0 | AW45: 0 | AX45: 0 | AY45: 0 | AZ45: 0 | BA45: 0 | BB45: 0
B46: Tổng
B48: LNG
A50: 1 | B50: LNG
B51: Bán vật tư y tế | J51: =J9-J33 -> 5.5527225 | K51: =K9-K33 -> 6.5474174 | L51: =L9-L33 -> 3.3644158 | M51: =M9-M33 -> -10.12155 | N51: =N9-N33 -> -0.72008382 | O51: =O9-O33 -> 8.833358 | P51: =P9-P33 -> 29.119157 | Q51: =Q9*Q57 -> 5.0822278 | R51: =R9*R57 -> 6.4787448 | S51: =S9*S57 -> 7.7744938 | T51: =T9*T57 -> 8.5519431 | U51: =U9*U57 -> 8.9795403 | V51: =V9*V57 -> 9.4285173 | W51: =W9*W57 -> 9.8999432 | X51: =X9*X57 -> 10.196941 | ... AB51: =AB9*AB57 -> 11.476747 | AC51: 0 | AD51: 0 | AE51: 0 | AF51: 0 | AG51: 0 | AH51: 0 | AI51: 0 | AJ51: 0 | AK51: 0 | AL51: 0 | AM51: 0 | AN51: 0 | AO51: 0 | AP51: 0 | AQ51: 0 | AR51: 0 | AS51: 0 | AT51: 0 | AU51: 0 | AV51: 0 | AW51: 0 | AX51: 0 | AY51: 0 | AZ51: 0 | BA51: 0 | BB51: 0
B52: Bán nguyên liệu,bao bì, công cụ, dụng cụ,khác | J52: =J10-J34 -> 1.9040592 | K52: =K10-K34 -> -3.5914072 | L52: =L10-L34 -> -0.73343403 | M52: =M10-M34 -> -0.28388259 | N52: =N10-N34 -> 1.2295995 | O52: =O10-O34 -> 3.3349758 | P52: =P10-P34 -> 0.26433239 | Q52: =Q10*Q58 -> 0.086035661 | R52: =R10*R58 -> 0.09646022 | S52: =S10*S58 -> 0.10224783 | T52: =T10*T58 -> 0.1083827 | U52: =U10*U58 -> 0.11488567 | V52: =V10*V58 -> 0.12177881 | W52: =W10*W58 -> 0.12908553 | X52: =X10*X58 -> 0.1329581 | ... BB52: =BB10*BB58 -> 0
B53: Tổng | J53: =J51+J52 -> 7.4567817 | K53: =K51+K52 -> 2.9560102 | L53: =L51+L52 -> 2.6309818 | M53: =M51+M52 -> -10.405433 | N53: =N51+N52 -> 0.50951571 | O53: =O51+O52 -> 12.168334 | P53: =P51+P52 -> 29.383489 | Q53: =Q51+Q52 -> 5.1682635 | ... BB53: =BB51+BB52 -> 0
B54: Growth
...

Sheet Consol. Rev.
B1: 1 | N1: 1 | O1: 2 | P1: 3 | Q1: 4 | R1: 5 | S1: 6 | T1: 7 | U1: 8 | V1: 9 | W1: 10 | X1: 11 | Y1: 12 | Z1: 13 | AA1: 14 | AB1: 15 | AC1: 16 | AD1: 17 | AE1: 18 | AF1: 19 | AG1: 20 | AH1: 21 | AI1: 22 | AJ1: 23 | AK1: 24 | AL1: 25 | AM1: 26 | AN1: 27 | AO1: 28 | AP1: 29 | AQ1: 30 | AR1: 31 | AS1: 32 | AT1: 33 | AU1: 34 | AV1: 35 | AW1: 36 | AX1: 37 | AY1: 38 | AZ1: 39 | BA1: 40
C2: =IF(TODAY()<C3,"Proj","") | D2: =IF(TODAY()<D3,"Proj","") | F2: =IF(TODAY()<F3,"Proj","") | G2: =IF(TODAY()<G3,"Proj","") | H2: =IF(TODAY()<H3,"Proj","") | I2: =IF(TODAY()<I3,"Proj","") | J2: =IF(TODAY()<J3,"Proj","") | K2: =IF(TODAY()<K3,"Proj","") | L2: =IF(TODAY()<L3,"Proj","") | M2: =IF(TODAY()<M3,"Proj","") | ... BA2: =IF(TODAY()<BA3,"Proj","") -> Proj
D3: 40178 | E3: =DATE(YEAR(D3),MONTH(D3)+13,0) -> 40543 | F3: =DATE(YEAR(E3),MONTH(E3)+13,0) -> 40908 | G3: =DATE(YEAR(F3),MONTH(F3)+13,0) -> 41274 | H3: =DATE(YEAR(G3),MONTH(G3)+13,0) -> 41639 | I3: =DATE(YEAR(H3),MONTH(H3)+13,0) -> 42004 | J3: =DATE(YEAR(I3),MONTH(I3)+13,0) -> 42369 | K3: =DATE(YEAR(J3),MONTH(J3)+13,0) -> 42735 | L3: =DATE(YEAR(K3),MONTH(K3)+13,0) -> 43100 | ... BA3: =DATE(YEAR(AZ3),MONTH(AZ3)+13,0) -> 58075 | BC3: Notes
H4: % growth rev | J4: 0.12610028 | K4: -0.0035789674 | L4: -0.027707207 | M4: -0.063644704 | N4: 0.0045138828 | O4: 0.037228947 | P4: 0.26626816 | Q4: 0.02050258 | R4: 0.2737505 | S4: 0.063131553 | T4: 0.064186526 | U4: 0.048354073 | V4: 0.058773391 | W4: 0.039716983 | X4: 0.041545029 | Y4: 0.043423716 | Z4: 0.045348036
B6: REVENUE (price - sale - volume)
B8: Consol. revenue (FC) | J8: =SUM(J9:J11) -> 1236.79 | K8: =SUM(K9:K11) -> 1395.76 | L8: =SUM(L9:L11) -> 1404.34 | M8: =SUM(M9:M11) -> 1411.69 | N8: =SUM(N9:N11) -> 1277.13 | O8: =SUM(O9:O11) -> 1273.31 | P8: =SUM(P9:P11) -> 1573.08 | Q8: =SUM(Q9:Q11) -> 1674.6242 | ... AB8: =SUM(AB9:AB11) -> 361.60489
B9: Mảng dược phẩm | J9: ='Mảng dược phẩm'!M30 -> 1119.03 | K9: ='Mảng dược phẩm'!N30 -> 1260.14 | L9: ='Mảng dược phẩm'!O30 -> 1255.63 | M9: ='Mảng dược phẩm'!P30 -> 1220.84 | N9: ='Mảng dược phẩm'!Q30 -> 1143.14 | O9: ='Mảng dược phẩm'!R30 -> 1148.3 | P9: ='Mảng dược phẩm'!S30 -> 1191.05 | Q9: ='Mảng dược phẩm'!T30 -> 1508.1887 | ... AB9: ='Mảng dược phẩm'!AE30 -> 0
