Workbook

Sheet IS Raw
A5: Tính năng | B5: Kết quả kinh doanh - DCM
A6: Ngày trích xuất | B6: 45860.705
A8: Mã CK | B8: DCM | D8: Xem theo | E8: Hằng năm | F8: 2025
A9: Loại | B9: Hợp nhất | D9: Tiền tệ | E9: VND | F9: Tỷ VND
A11: Chỉ tiêuTỷ VND | B11: 2015 | C11: 2016 | D11: 2017 | E11: 2018 | F11: 2019 | G11: 2020 | H11: 2021 | I11: 2022 | J11: 2023 | K11: 2024
A12: Trạng thái kiểm toán | B12: Đã kiểm toán | C12: Đã kiểm toán | D12: Đã kiểm toán | E12: Đã kiểm toán | F12: Đã kiểm toán | G12: Đã kiểm toán | H12: Đã kiểm toán | I12: Đã kiểm toán | J12: Đã kiểm toán | K12: Đã kiểm toán
A13: Công ty kiểm toán | B13: Deloitte Vietnam Audit Co., Ltd | C13: Deloitte Vietnam Audit Co., Ltd | D13: Deloitte Vietnam Audit Co., Ltd | F13: Deloitte Vietnam Audit Co., Ltd | G13: Deloitte Vietnam Audit Co., Ltd | H13: PwC Vietnam | I13: Deloitte Vietnam Audit Co., Ltd | J13: Deloitte Vietnam Audit Co., Ltd | K13: Deloitte Vietnam Audit Co., Ltd
A14: Loại ý kiến kiểm toán | B14: Chấp nhận toàn phần | C14: Chấp nhận toàn phần | D14: Chấp nhận toàn phần | F14: Chấp nhận toàn phần | G14: Chấp nhận toàn phần | H14: Chấp nhận toàn phần | I14: Chấp nhận toàn phần | J14: Chấp nhận toàn phần | K14: Chấp nhận toàn phần
A15: Doanh thu bán hàng và cung cấp dịch vụ | B15: 6002.7467 | C15: 4971.7489 | D15: 5832.9733 | E15: 6827.3338 | F15: 7176.5755 | G15: 7716.8905 | H15: 10088.157 | I15: 16380.04 | J15: 12949.489 | K15: 13942.548
A16: Các khoản giảm trừ doanh thu | B16: -94.14422 | C16: -61.57826 | D16: -85.218359 | E16: -138.00525 | F16: -133.60855 | G16: -155.61538 | H16: -218.39418 | I16: -455.5129 | J16: -378.94707 | K16: -486.9631
A17: Doanh thu thuần | B17: 5908.6025 | C17: 4910.1707 | D17: 5747.755 | E17: 6689.3285 | F17: 7042.9669 | G17: 7561.2751 | H17: 9869.7629 | I17: 15924.527 | J17: 12570.542 | K17: 13455.585
A18: Giá vốn hàng bán | B18: -4098.6635 | C18: -3595.5077 | D18: -4366.4525 | E18: -5252.2705 | F18: -6083.7747 | G18: -6244.4273 | H18: -7088.826 | I18: -10221.097 | J18: -10538.742 | K18: -10942.101
A19: Lợi nhuận gộp về bán hàng và cung cấp dịch vụ | B19: 1809.939 | C19: 1314.6629 | D19: 1381.3025 | E19: 1437.058 | F19: 959.1922 | G19: 1316.8478 | H19: 2780.9369 | I19: 5703.4294 | J19: 2031.7997 | K19: 2513.4843
A20: Doanh thu hoạt động tài chính | B20: 232.67253 | C20: 281.35201 | D20: 168.76274 | E20: 176.15302 | F20: 127.01614 | G20: 128.31668 | H20: 167.53191 | I20: 301.00806 | J20: 577.08849 | K20: 381.8039
A21: Chi phí tài chính | B21: -648.18169 | C21: -432.71948 | D21: -202.88878 | E21: -260.13015 | F21: -102.75348 | G21: -63.234525 | H21: -45.07293 | I21: -60.402057 | J21: -27.372488 | K21: -76.569108
A22: Trong đó: Chi phí lãi vay | B22: -242.45234 | C22: -206.62239 | D22: -182.98653 | E22: -142.05277 | F22: -87.17253 | G22: -43.301059 | H22: -18.580201 | I22: -10.274784 | J22: -10.155714 | K22: -44.380805
A23: Lãi/(lỗ) từ công ty liên doanh (từ năm 2015) | B23: 0 | C23: 0 | D23: 0 | E23: 0 | F23: 0 | G23: 0 | H23: 0 | I23: 0 | J23: 0 | K23: 0
A24: Chi phí bán hàng | B24: -275.65392 | C24: -275.83301 | D24: -333.60031 | E24: -336.1147 | F24: -364.0587 | G24: -369.00032 | H24: -420.40125 | I24: -698.29487 | J24: -800.63146 | K24: -1014.3698
A25: Chi phí quản lý doanh nghiệp | B25: -203.31141 | C25: -254.75383 | D25: -337.35087 | E25: -320.10336 | F25: -201.3192 | G25: -304.40666 | H25: -528.49174 | I25: -652.59426 | J25: -548.55689 | K25: -481.047
A26: Lãi/(lỗ) từ hoạt động kinh doanh | B26: 915.46453 | C26: 632.70863 | D26: 676.22523 | E26: 696.86285 | F26: 418.07696 | G26: 708.52298 | H26: 1954.5029 | I26: 4593.1463 | J26: 1232.3273 | K26: 1323.3022
... A39: Lãi trên cổ phiếu pha loãng (VND) | B39: 0 | C39: 0 | D39: 0 | E39: 0 | F39: 0 | G39: 0 | H39: 3073 | I39: 0 | J39: 0 | K39: 0
A41: Contact
A42: CÔNG TY CỔ PHẦN FIINGROUP VIỆT NAM
A43: Trụ sở: Tầng 10, Tòa nhà PeakView, 36 Hoàng Cầu, Đống Đa, Hà Nội, Việt Nam
A44: Chi nhánh: Tầng 16, Tòa nhà Bitexco Financial Tower, số 2 Hải Triều , Phường Bến Nghé, Quận 1, TP. Hồ Chí Minh, Việt Nam
A45: Website: https://fiingroup.vn
A47: TRUNG TÂM CHĂM SÓC KHÁCH HÀNG
A48: T: (84-24) - 3562 6962 - Ext: 103
A49: Email: fiinpro.support@fiingroup.vn

Sheet BS Raw
A5: Tính năng | B5: Bảng cân đối kế toán - DCM
A6: Ngày trích xuất | B6: 45860.705
A8: Mã CK | B8: DCM | D8: Xem theo | E8: Hằng năm | F8: 2025
A9: Loại | B9: Hợp nhất | D9: Tiền tệ | E9: VND | F9: Tỷ VND
A11: Chỉ tiêuTỷ VND | B11: 2015 | C11: 2016 | D11: 2017 | E11: 2018 | F11: 2019 | G11: 2020 | H11: 2021 | I11: 2022 | J11: 2023 | K11: 2024
A12: Trạng thái kiểm toán | B12: Đã kiểm toán | C12: Đã kiểm toán | D12: Đã kiểm toán | E12: Đã kiểm toán | F12: Đã kiểm toán | G12: Đã kiểm toán | H12: Đã kiểm toán | I12: Đã kiểm toán | J12: Đã kiểm toán | K12: Đã kiểm toán
A13: Công ty kiểm toán | B13: Deloitte Vietnam Audit Co., Ltd | C13: Deloitte Vietnam Audit Co., Ltd | D13: Deloitte Vietnam Audit Co., Ltd | F13: Deloitte Vietnam Audit Co., Ltd | G13: Deloitte Vietnam Audit Co., Ltd | H13: PwC Vietnam | I13: Deloitte Vietnam Audit Co., Ltd | J13: Deloitte Vietnam Audit Co., Ltd | K13: Deloitte Vietnam Audit Co., Ltd
A14: Loại ý kiến kiểm toán | B14: Chấp nhận toàn phần | C14: Chấp nhận toàn phần | D14: Chấp nhận toàn phần | F14: Chấp nhận toàn phần | G14: Chấp nhận toàn phần | H14: Chấp nhận toàn phần | I14: Chấp nhận toàn phần | J14: Chấp nhận toàn phần | K14: Chấp nhận toàn phần
A15: TÀI SẢN NGẮN HẠN | B15: 4431.3566 | C15: 4034.4151 | D15: 4838.7091 | E15: 4318.349 | F15: 4250.037 | G15: 3978.1921 | H15: 7276.2916 | I15: 11624.187 | J15: 13504.495 | K15: 12920.863
A16: Tiền và tương đương tiền | B16: 1215.0793 | C16: 813.51875 | D16: 1896.1849 | E16: 285.77246 | F16: 471.17332 | G16: 509.99535 | H16: 427.65273 | I16: 2125.6253 | J16: 2284.3998 | K16: 1903.2483
A17: Tiền | B17: 183.07933 | C17: 481.51875 | D17: 393.83489 | E17: 165.77246 | F17: 371.17332 | G17: 289.99535 | H17: 427.65273 | I17: 2125.6253 | J17: 2274.3998 | K17: 1903.2483
A18: Các khoản tương đương tiền | B18: 1032 | C18: 332 | D18: 1502.35 | E18: 120 | F18: 100 | G18: 220 | H18: 0 | I18: 0 | J18: 10 | K18: 0
A19: Giá trị thuần đầu tư ngắn hạn | B19: 2702.5556 | C19: 2300 | D19: 2100 | E19: 2502 | F19: 2002 | G19: 2302 | H19: 4362 | I19: 6812 | J19: 8242 | K19: 7039.0512
A20: Đầu tư ngắn hạn | B20: 0 | C20: 0 | D20: 0 | E20: 0 | F20: 0 | G20: 0 | H20: 0 | I20: 0 | J20: 0 | K20: 0
A21: Dự phòng đầu tư ngắn hạn | B21: 0 | C21: 0 | D21: 0 | E21: 0 | F21: 0 | G21: 0 | H21: 0 | I21: 0 | J21: 0 | K21: 0
A22: Đầu tư nắm giữ đến ngày đáo hạn | B22: 2702.5556 | C22: 2300 | D22: 2100 | E22: 2502 | F22: 2002 | G22: 2302 | H22: 4362 | I22: 6812 | J22: 8242 | K22: 7039.0512
A23: Các khoản phải thu | B23: 79.842094 | C23: 481.71633 | D23: 400.47866 | E23: 452.94998 | F23: 401.90973 | G23: 217.3963 | H23: 187.45808 | I23: 188.14971 | J23: 365.83833 | K23: 528.62319
A24: Phải thu khách hàng | B24: 7.2613277 | C24: 6.8141083 | D24: 1.2981874 | E24: 17.543502 | F24: 2.9264002 | G24: 44.753555 | H24: 44.653507 | I24: 1.4047958 | J24: 198.51199 | K24: 298.9049
A25: Trả trước người bán | B25: 14.976365 | C25: 18.741754 | D25: 88.361011 | E25: 86.367566 | F25: 55.315028 | G25: 15.505616 | H25: 86.006714 | I25: 86.290004 | J25: 54.781184 | K25: 225.764
A26: Phải thu nội bộ | B26: 0 | C26: 0 | D26: 0 | E26: 0 | F26: 0 | G26: 0 | H26: 0 | I26: 0 | J26: 0 | K26: 0
... A108: Thuế thu nhập hoãn lại phải trả | B108: 0 | C108: 0 | D108: 0 | E108: 0 | F108: 0 | G108: 0 | H108: 0 | I108: 0 | J108: 0 | K108: 0
A109: Dự phòng trợ cấp thôi việc
A110: Dự phòng các khoản công nợ dài hạn | B110: 0 | C110: 0 | D110: 0 | E110: 0 | F110: 0 | G110: 0 | H110: 0 | I110: 0 | J110: 0 | K110: 0
A111: Quỹ phát triển khoa học công nghệ | B111: 35.127225 | C111: 41.572332 | D111: 103.43752 | E111: 156.50848 | F111: 137.79715 | G111: 203.81901 | H111: 404.73717 | I111: 685.92744 | J111: 754.36092 | K111: 751.41313
A112: VỐN CHỦ SỞ HỮU | B112: 6233.1928 | C112: 5850.2431 | D112: 6153.522 | E112: 6268.8723 | F112: 6106.3273 | G112: 6326.4477 | H112: 7478.0973 | I112: 10605.449 | J112: 9963.3832 | K112: 10177.177
A113: Vốn và các quỹ | B113: 6233.1928 | C113: 5850.2431 | D113: 6153.522 | E113: 6268.8723 | F113: 6106.3273 | G113: 6326.4477 | H113: 7478.0973 | I113: 10605.449 | J113: 9963.3832 | K113: 10177.177
A114: Vốn góp | B114: 5294 | C114: 5294 | D114: 5294 | E114: 5294 | F114: 5294 | G114: 5294 | H114: 5294 | I114: 5294 | J114: 5294 | K114: 5294
A115: Cổ phiếu phổ thông | B115: 5294 | C115: 5294 | D115: 5294 | E115: 5294 | F115: 5294 | G115: 5294 | H115: 5294 | I115: 5294 | J115: 5294 | K115: 5294
A116: Cổ phiếu ưu đãi | B116: 0 | C116: 0 | D116: 0 | E116: 0 | F116: 0 | G116: 0 | H116: 0 | I116: 0 | J116: 0 | K116: 0
A117: Thặng dư vốn cổ phần | B117: 0 | C117: 0 | D117: 0 | E117: 0 | F117: 0 | G117: 0 | H117: 0 | I117: 0 | J117: 0 | K117: 0
A118: Quyền chọn chuyển đổi trái phiếu | B118: 0 | C118: 0 | D118: 0 | E118: 0 | F118: 0 | G118: 0 | H118: 0 | I118: 0 | J118: 0 | K118: 0
A119: Vốn khác | B119: 0 | C119: 0 | D119: 0 | E119: 2.49915 | F119: 3.66542 | G119: 3.66542 | H119: 3.66542 | I119: 3.66542 | J119: 3.66542 | K119: 3.66542
A120: Cổ phiếu quỹ | B120: 0 | C120: 0 | D120: 0 | E120: 0 | F120: 0 | G120: 0 | H120: 0 | I120: 0 | J120: 0 | K120: 0
A121: Chênh lệch đánh giá lại tài sản | B121: 0 | C121: 0 | D121: 0 | E121: 0 | F121: 0 | G121: 0 | H121: 0 | I121: 0 | J121: 0 | K121: 0
... A124: Quỹ hỗ trợ sắp xếp doanh nghiệp | B124: 0 | C124: 0 | D124: 0 | E124: 0 | F124: 0 | G124: 0 | H124: 0 | I124: 0 | J124: 0 | K124: 0
A125: Quỹ dự phòng tài chính
A126: Quỹ khác | B126: 0 | C126: 0 | D126: 0 | E126: 0 | F126: 0 | G126: 0 | H126: 0 | I126: 0 | J126: 0 | K126: 0
A127: Lãi chưa phân phối | B127: 543.4136 | C127: 368.28854 | D127: 594.40372 | E127: 626.04216 | F127: 428.84563 | G127: 583.46741 | H127: 1187.9854 | I127: 3018.4551 | J127: 2044.8513 | K127: 1882.5131
A128: LNST chưa phân phối lũy kế đến cuối kỳ trước | B128: 1.6456001 | C128: 0.57033728 | D128: 98.105509 | E128: 114.02546 | F128: 146.20975 | G128: 110.77882 | H128: 106.42934 | I128: 234.72596 | J128: 1425.163 | K128: 984.14775
A129: LNST chưa phân phối kỳ này | B129: 541.768 | C129: 367.7182 | D129: 496.29821 | E129: 512.0167 | F129: 282.63589 | G129: 472.68859 | H129: 1081.5561 | I129: 2783.7291 | J129: 619.68831 | K129: 898.36535
...

Sheet CF Raw
A5: Tính năng | B5: Lưu chuyển tiền tệ - DCM
A6: Ngày trích xuất | B6: 45860.705
A8: Mã CK | B8: DCM | D8: Xem theo | E8: Hằng năm | F8: 2025
A9: Loại | B9: Hợp nhất | D9: Tiền tệ | E9: VND | F9: Tỷ VND
A11: Chỉ tiêuTỷ VND | B11: 2015 | C11: 2016 | D11: 2017 | E11: 2018 | F11: 2019 | G11: 2020 | H11: 2021 | I11: 2022 | J11: 2023 | K11: 2024
A12: Trạng thái kiểm toán | B12: Đã kiểm toán | C12: Đã kiểm toán | D12: Đã kiểm toán | E12: Đã kiểm toán | F12: Đã kiểm toán | G12: Đã kiểm toán | H12: Đã kiểm toán | I12: Đã kiểm toán | J12: Đã kiểm toán | K12: Đã kiểm toán
A13: Công ty kiểm toán | B13: Deloitte Vietnam Audit Co., Ltd | C13: Deloitte Vietnam Audit Co., Ltd | D13: Deloitte Vietnam Audit Co., Ltd | F13: Deloitte Vietnam Audit Co., Ltd | G13: Deloitte Vietnam Audit Co., Ltd | H13: PwC Vietnam | I13: Deloitte Vietnam Audit Co., Ltd | J13: Deloitte Vietnam Audit Co., Ltd | K13: Deloitte Vietnam Audit Co., Ltd
A14: Loại ý kiến kiểm toán | B14: Chấp nhận toàn phần | C14: Chấp nhận toàn phần | D14: Chấp nhận toàn phần | F14: Chấp nhận toàn phần | G14: Chấp nhận toàn phần | H14: Chấp nhận toàn phần | I14: Chấp nhận toàn phần | J14: Chấp nhận toàn phần | K14: Chấp nhận toàn phần
A15: Lợi nhuận/(lỗ) trước thuế | B15: 859.23791 | C15: 658.89139 | D15: 679.32513 | E15: 706.19864 | F15: 463.08817 | G15: 716.5338 | H15: 1956.27 | I15: 4596.3128 | J15: 1254.8096 | K15: 1522.0635
A16: Khấu hao TSCĐ và BĐSĐT | B16: 1279.6765 | C16: 1292.0368 | D16: 1309.0006 | E16: 1303.3756 | F16: 1318.8406 | G16: 1318.1525 | H16: 1385.8109 | I16: 1398.0294 | J16: 1083.3807 | K16: 268.08146
A17: Phân bổ lợi thế thương mại | B17: 0 | C17: 0 | D17: 0 | E17: 0 | F17: 0 | G17: 0 | H17: 0 | I17: 0 | J17: 0 | K17: 0
A18: Chi phí dự phòng | B18: 0.71284767 | C18: 0.79221648 | D18: -1.5050641 | E18: 0 | F18: 8.9182587 | G18: -8.4816782 | H18: 37.053214 | I18: 822.62005 | J18: -212.57578 | K18: 9.4771195
A19: Lãi/lỗ chênh lệch tỷ giá hối đoái do đánh giá lại các khoản mục tiền tệ có gốc ngoại tệ | B19: 275.36748 | C19: 72.779574 | D19: -10.234614 | E19: 49.850496 | F19: -2.435473 | G19: -1.5350377 | H19: -7.0093268 | I19: 9.3273665 | J19: -43.609637 | K19: 2.9503122
A20: Lãi/(lỗ) từ thanh lý tài sản cố định | B20: 0 | C20: 0 | D20: 0 | E20: 0 | F20: 0 | G20: 0 | H20: 0 | I20: 0 | J20: 0 | K20: 0
A21: (Lãi)/lỗ từ hoạt động đầu tư | B21: -173.04781 | C21: -155.76618 | D21: -156.68025 | E21: -158.47635 | F21: -117.69981 | G21: -111.92758 | H21: -130.83572 | I21: -265.29046 | J21: -518.47533 | K21: -451.85853
A22: Chi phí lãi vay | B22: 242.45234 | C22: 206.62239 | D22: 182.98653 | E22: 142.05277 | F22: 87.17253 | G22: 43.301059 | H22: 18.580201 | I22: 10.274784 | J22: 10.155714 | K22: 44.380805
A23: Thu lãi và cổ tức | B23: 0 | C23: 0 | D23: 0 | E23: 0 | F23: 0 | G23: 0 | H23: 0 | I23: 0 | J23: 0 | K23: 0
A24: Các khoản điều chỉnh khác | B24: 16.12 | C24: 15 | D24: 72.825538 | E24: 71.305674 | F24: 0 | G24: 79.425415 | H24: 216.72828 | I24: 318.81693 | J24: 108.88589 | K24: 40.507659
A25: Lợi nhuận/(lỗ) từ hoạt động kinh doanh trước những thay đổi vốn lưu động | B25: 2500.5193 | C25: 2090.3561 | D25: 2075.7178 | E25: 2114.3069 | F25: 1757.8843 | G25: 2035.4684 | H25: 3476.5976 | I25: 6890.0908 | J25: 1682.5711 | K25: 1435.6023
A26: (Tăng)/giảm các khoản phải thu | B26: -1.2185283 | C26: -422.50323 | D26: 27.973718 | E26: -48.477093 | F26: 55.14422 | G26: 135.33961 | H26: 30.360921 | I26: -50.564994 | J26: -140.25581 | K26: -40.518052
... A55: Tiền và tương đương tiền cuối kỳ | B55: 1215.0793 | C55: 813.51875 | D55: 1896.1849 | E55: 285.77246 | F55: 471.17332 | G55: 509.99535 | H55: 427.65273 | I55: 2125.6253 | J55: 2284.3998 | K55: 1903.2483
A57: Contact
A58: CÔNG TY CỔ PHẦN FIINGROUP VIỆT NAM
A59: Trụ sở: Tầng 10, Tòa nhà PeakView, 36 Hoàng Cầu, Đống Đa, Hà Nội, Việt Nam
A60: Chi nhánh: Tầng 16, Tòa nhà Bitexco Financial Tower, số 2 Hải Triều , Phường Bến Nghé, Quận 1, TP. Hồ Chí Minh, Việt Nam
A61: Website: https://fiingroup.vn
A63: TRUNG TÂM CHĂM SÓC KHÁCH HÀNG
A64: T: (84-24) - 3562 6962 - Ext: 103
A65: Email: fiinpro.support@fiingroup.vn

Sheet Notes
A5: Tính năng | B5: Thuyết minh - DCM
A6: Ngày trích xuất | B6: 45860.705
A8: Mã CK | B8: DCM | D8: Xem theo | E8: Hằng năm | F8: 2025
A9: Loại | B9: Hợp nhất | D9: Tiền tệ | E9: VND | F9: Tỷ VND
A11: Chỉ tiêuTỷ VND | B11: 2015 | C11: 2016 | D11: 2017 | E11: 2018 | F11: 2019 | G11: 2020 | H11: 2021 | I11: 2022 | J11: 2023 | K11: 2024
A12: Trạng thái kiểm toán | B12: Đã kiểm toán | C12: Đã kiểm toán | D12: Đã kiểm toán | E12: Đã kiểm toán | F12: Đã kiểm toán | G12: Đã kiểm toán | H12: Đã kiểm toán | I12: Đã kiểm toán | J12: Đã kiểm toán | K12: Đã kiểm toán
A13: Công ty kiểm toán | B13: Deloitte Vietnam Audit Co., Ltd | C13: Deloitte Vietnam Audit Co., Ltd | D13: Deloitte Vietnam Audit Co., Ltd | F13: Deloitte Vietnam Audit Co., Ltd | G13: Deloitte Vietnam Audit Co., Ltd | H13: PwC Vietnam | I13: Deloitte Vietnam Audit Co., Ltd | J13: Deloitte Vietnam Audit Co., Ltd | K13: Deloitte Vietnam Audit Co., Ltd
A14: Loại ý kiến kiểm toán | B14: Chấp nhận toàn phần | C14: Chấp nhận toàn phần | D14: Chấp nhận toàn phần | F14: Chấp nhận toàn phần | G14: Chấp nhận toàn phần | H14: Chấp nhận toàn phần | I14: Chấp nhận toàn phần | J14: Chấp nhận toàn phần | K14: Chấp nhận toàn phần
A15: Tiền và tương đương tiền | B15: 1215.0793 | C15: 813.51875 | D15: 1896.1849 | E15: 285.77246 | F15: 471.17332 | G15: 509.99535 | H15: 427.65273 | I15: 2125.6253 | J15: 2284.3998 | K15: 1903.2483
A16: Tiền mặt | B16: 0.30402393 | C16: 0.084430897 | D16: 0.33197281 | E16: 0.95882405 | F16: 0.95280738 | G16: 1.0129324 | H16: 1.4409266 | I16: 0.94037573 | J16: 2.1446524 | K16: 1.7810592
A17: Tiền gửi Ngân hàng | B17: 182.77531 | C17: 481.43432 | D17: 393.50292 | E17: 164.81364 | F17: 370.22052 | G17: 288.98242 | H17: 426.2118 | I17: 2124.6849 | J17: 2272.2551 | K17: 1901.4673
A18: Tiền đang chuyển | B18: 0 | C18: 0 | D18: 0 | E18: 0 | F18: 0 | G18: 0 | H18: 0 | I18: 0 | J18: 0 | K18: 0
A19: Tiền và tương đương tiền | B19: 1032 | C19: 332 | D19: 1502.35 | E19: 120 | F19: 100 | G19: 220 | H19: 0 | I19: 0 | J19: 10 | K19: 0
A20: Đầu tư tài chính NH | B20: 2702.5556 | C20: 2300 | D20: 2100 | E20: 2502 | F20: 2002 | G20: 2302 | H20: 4362 | I20: 6812 | J20: 8242 | K20: 7039.0512
A21: Chứng khoán đầu tư ngắn hạn | B21: 0 | C21: 0 | D21: 0 | E21: 0 | F21: 0 | G21: 0 | H21: 0 | I21: 0 | J21: 0 | K21: 0
A22: Đầu tư nắm giữ đến ngày đáo hạn | B22: 2702.5556 | C22: 2300 | D22: 2100 | E22: 2502 | F22: 2002 | G22: 2302 | H22: 4362 | I22: 6812 | J22: 8242 | K22: 7039.0512
A23: Đầu tư ngắn hạn | B23: 2702.5556 | C23: 2300 | D23: 2100 | E23: 2502 | F23: 2002 | G23: 2302 | H23: 4362 | I23: 6812 | J23: 8242 | K23: 7039.0512
A24: Đầu tư dài hạn | B24: 0 | C24: 0 | D24: 0 | E24: 0 | F24: 0 | G24: 0 | H24: 0 | I24: 0 | J24: 0 | K24: 0
A25: Đầu tư NH khác | B25: 0 | C25: 0 | D25: 0 | E25: 0 | F25: 0 | G25: 0 | H25: 0 | I25: 0 | J25: 0 | K25: 0
A26: Dự phòng giảm giá ĐTNH | B26: 0 | C26: 0 | D26: 0 | E26: 0 | F26: 0 | G26: 0 | H26: 0 | I26: 0 | J26: 0 | K26: 0
... A171: Chi phí khác bằng tiền | B171: 0 | C171: 99.486096 | D171: 322.76439 | E171: 412.57102 | F171: 293.90204 | G171: 364.34541 | H171: 743.85104 | I171: 867.12225 | J171: 608.16808 | K171: 688.0484
A173: Contact
A174: CÔNG TY CỔ PHẦN FIINGROUP VIỆT NAM
A175: Trụ sở: Tầng 10, Tòa nhà PeakView, 36 Hoàng Cầu, Đống Đa, Hà Nội, Việt Nam
A176: Chi nhánh: Tầng 16, Tòa nhà Bitexco Financial Tower, số 2 Hải Triều , Phường Bến Nghé, Quận 1, TP. Hồ Chí Minh, Việt Nam
A177: Website: https://fiingroup.vn
A179: TRUNG TÂM CHĂM SÓC KHÁCH HÀNG
A180: T: (84-24) - 3562 6962 - Ext: 103
A181: Email: fiinpro.support@fiingroup.vn

Sheet Doanh thu DCM
A1: BREAKDOWN | D1: 2019 | E1: =D1+1 -> 2020 | F1: =E1+1 -> 2021 | G1: =F1+1 -> 2022 | H1: =G1+1 -> 2023 | I1: =H1+1 -> 2024 | J1: =I1+1 -> 2025 | K1: =J1+1 -> 2026 | L1: =K1+1 -> 2027 | ... S1: =R1+1 -> 2034
J2: projected | K2: =J2 -> projected | L2: =K2 -> projected | M2: =L2 -> projected | N2: =M2 -> projected | O2: =N2 -> projected | P2: =O2 -> projected | Q2: =P2 -> projected | R2: =Q2 -> projected | S2: =R2 -> projected | U2: FO 180 tại Singapore vào ngày 23 tháng 9 năm 2025 là 403.37 USD/tấn
A3: SUMMARY STATISTICS | U3: https://www.sgx.com/derivatives/products/fuel-oil-380cst
B5: DPM Data
B6: Revenue | D6: ='IS Raw'!F15 -> 7176.5755 | E6: ='IS Raw'!G15 -> 7716.8905 | F6: ='IS Raw'!H15 -> 10088.157 | G6: ='IS Raw'!I15 -> 16380.04 | H6: ='IS Raw'!J15 -> 12949.489 | I6: ='IS Raw'!K15 -> 13942.548 | J6: =J9/(100%-J8) -> 16634.065 | K6: =K9/(100%-K8) -> 17303.93 | L6: =L9/(100%-L8) -> 17415.173 | M6: =M9/(100%-M8) -> 20041.613 | N6: =N9/(100%-N8) -> 19135.1 | O6: =O9/(100%-O8) -> 17899.264 | P6: =P9/(100%-P8) -> 17943.869 | Q6: =Q9/(100%-Q8) -> 18009.288 | ... S6: =S9/(100%-S8) -> 18363.343
B7: Reductions | D7: =-'IS Raw'!F16 -> 133.60855 | E7: =-'IS Raw'!G16 -> 155.61538 | F7: =-'IS Raw'!H16 -> 218.39418 | G7: =-'IS Raw'!I16 -> 455.5129 | H7: =-'IS Raw'!J16 -> 378.94707 | I7: =-'IS Raw'!K16 -> 486.9631 | J7: =J6-J9 -> 422.58938 | K7: =K6-K9 -> 439.60733 | L7: =L6-L9 -> 442.43347 | M7: =M6-M9 -> 509.15831 | N7: =N6-N9 -> 486.1283 | O7: =O6-O9 -> 454.73182 | P7: =P6-P9 -> 455.86501 | Q7: =Q6-Q9 -> 457.527 | ... S7: =S6-S9 -> 466.52179
B8: %Reductions | D8: =D7/D6 -> 0.018617313 | E8: =E7/E6 -> 0.020165555 | F8: =F7/F6 -> 0.02164857 | G8: =G7/G6 -> 0.027809023 | H8: =H7/H6 -> 0.029263477 | I8: =I7/I6 -> 0.034926406 | J8: =AVERAGE(D8:I8) -> 0.025405057 | K8: =J8 -> 0.025405057 | L8: =K8 -> 0.025405057 | M8: =L8 -> 0.025405057 | N8: =M8 -> 0.025405057 | O8: =N8 -> 0.025405057 | P8: =O8 -> 0.025405057 | Q8: =P8 -> 0.025405057 | R8: =Q8 -> 0.025405057 | S8: =R8 -> 0.025405057
B9: Net revenue | D9: ='IS Raw'!F17 -> 7042.9669 | E9: ='IS Raw'!G17 -> 7561.2751 | F9: ='IS Raw'!H17 -> 9869.7629 | G9: ='IS Raw'!I17 -> 15924.527 | H9: ='IS Raw'!J17 -> 12570.542 | I9: ='IS Raw'!K17 -> 13455.585 | J9: =J112+J159+J170+J194+J241 -> 16211.476 | K9: =K112+K159+K170+K194+K241 -> 16864.323 | L9: =L112+L159+L170+L194+L241 -> 16972.74 | M9: =M112+M159+M170+M194+M241 -> 19532.454 | N9: =N112+N159+N170+N194+N241 -> 18648.971 | O9: =O112+O159+O170+O194+O241 -> 17444.532 | P9: =P112+P159+P170+P194+P241 -> 17488.004 | Q9: =Q112+Q159+Q170+Q194+Q241 -> 17551.761 | ... S9: =S112+S159+S170+S194+S241 -> 17896.822
B10: % growth | E10: =E9/D9-1 -> 0.073592305 | F10: =F9/E9-1 -> 0.30530404 | G10: =G9/F9-1 -> 0.613466 | H10: =H9/G9-1 -> -0.21061755 | I10: =I9/H9-1 -> 0.070406117 | J10: =J9/I9-1 -> 0.2048139 | K10: =K9/J9-1 -> 0.040270654 | L10: =L9/K9-1 -> 0.0064287681 | ... S10: =S9/R9-1 -> -0.021470614
B11: COGS | D11: =-'IS Raw'!F18 -> 6083.7747 | E11: =-'IS Raw'!G18 -> 6244.4273 | F11: =-'IS Raw'!H18 -> 7088.826 | G11: =-'IS Raw'!I18 -> 10221.097 | H11: =-'IS Raw'!J18 -> 10538.742 | I11: =-'IS Raw'!K18 -> 10942.101 | J11: =J115+J165+J175+J197+J255 -> 12555.221 | K11: =K115+K165+K175+K197+K255 -> 12841.878 | L11: =L115+L165+L175+L197+L255 -> 12594.457 | M11: =M115+M165+M175+M197+M255 -> 13259.35 | N11: =N115+N165+N175+N197+N255 -> 13320.284 | O11: =O115+O165+O175+O197+O255 -> 12855.792 | P11: =P115+P165+P175+P197+P255 -> 13098.318 | Q11: =Q115+Q165+Q175+Q197+Q255 -> 12889.567 | ... S11: =S115+S165+S175+S197+S255 -> 13119.186
B12: Gross profit | D12: ='IS Raw'!F19 -> 959.1922 | E12: ='IS Raw'!G19 -> 1316.8478 | F12: ='IS Raw'!H19 -> 2780.9369 | G12: ='IS Raw'!I19 -> 5703.4294 | H12: ='IS Raw'!J19 -> 2031.7997 | I12: ='IS Raw'!K19 -> 2513.4843 | J12: =J9-J11 -> 3656.255 | K12: =K9-K11 -> 4022.4445 | L12: =L9-L11 -> 4378.2821 | M12: =M9-M11 -> 6273.1047 | N12: =N9-N11 -> 5328.6875 | O12: =O9-O11 -> 4588.7395 | P12: =P9-P11 -> 4389.6857 | Q12: =Q9-Q11 -> 4662.1944 | ... S12: =S9-S11 -> 4777.6353
B13: GPM | D13: =D12/D9 -> 0.1361915 | E13: =E12/E9 -> 0.17415684 | F13: =F12/F9 -> 0.2817633 | G13: =G12/G9 -> 0.35815378 | H13: =H12/H9 -> 0.16163183 | I13: =I12/I9 -> 0.18679858 | J13: =J12/J9 -> 0.22553499 | K13: =K12/K9 -> 0.238518 | ... S13: =S12/S9 -> 0.2669544
B14: Financial Income (tỷ đồng) | D14: ='IS Raw'!F20 -> 127.01614 | E14: ='IS Raw'!G20 -> 128.31668 | F14: ='IS Raw'!H20 -> 167.53191 | G14: ='IS Raw'!I20 -> 301.00806 | H14: ='IS Raw'!J20 -> 577.08849 | I14: ='IS Raw'!K20 -> 381.8039
B15: Financial X (chi phí tài chính) (tỷ đồng) | D15: =-'IS Raw'!F21 -> 102.75348 | E15: =-'IS Raw'!G21 -> 63.234525 | F15: =-'IS Raw'!H21 -> 45.07293 | G15: =-'IS Raw'!I21 -> 60.402057 | H15: =-'IS Raw'!J21 -> 27.372488 | I15: =-'IS Raw'!K21 -> 76.569108
B16: Selling X (chi phí bán hàng) (tỷ đồng) | D16: =-'IS Raw'!F24 -> 364.0587 | E16: =-'IS Raw'!G24 -> 369.00032 | F16: =-'IS Raw'!H24 -> 420.40125 | G16: =-'IS Raw'!I24 -> 698.29487 | H16: =-'IS Raw'!J24 -> 800.63146 | I16: =-'IS Raw'!K24 -> 1014.3698
B17: G&A X (Chi phí quản lý doanh nghiệp) (tỷ đồng) | D17: =-'IS Raw'!F25 -> 201.3192 | E17: =-'IS Raw'!G25 -> 304.40666 | F17: =-'IS Raw'!H25 -> 528.49174 | G17: =-'IS Raw'!I25 -> 652.59426 | H17: =-'IS Raw'!J25 -> 548.55689 | I17: =-'IS Raw'!K25 -> 481.047
B18: Other Income (thu nhập khác) (tỷ đồng) | D18: ='IS Raw'!F28 -> 48.48338 | E18: ='IS Raw'!G28 -> 10.735344 | F18: ='IS Raw'!H28 -> 4.3711954 | G18: ='IS Raw'!I28 -> 15.225626 | H18: ='IS Raw'!J28 -> 24.751516 | I18: ='IS Raw'!K28 -> 199.87676
B19: Other X (chi phí khác) (tỷ đồng) | D19: =-'IS Raw'!F29 -> 3.4721669 | E19: =-'IS Raw'!G29 -> 2.7245179 | F19: =-'IS Raw'!H29 -> 2.6041186 | G19: =-'IS Raw'!I29 -> 12.059178 | H19: =-'IS Raw'!J29 -> 2.2692702 | I19: =-'IS Raw'!K29 -> 1.1155147
B21: Projection Check
B23: Revenue (excluding NPK)
B24: Revenue
B25: Reductions
B26: %Reductions
B27: Net revenue
B28: %growth
B29: COGS
B30: Gross profit
B31: GPM
B32: Financial Income
B33: Financial X
... B37: Other X
B38: =B125 -> Oil price (USD/barrel) (brent)
B39: =B126 -> MFO (USD/ton)
B40: =B132 -> Natural Gas Price (USD/mmbtu) no VAT
B41: Selling X/Net R
B42: G&A/Net R
B43: Other income/Net R
B44: Other expense/Net R
A46: SALES BREAKDOWN BY PRODUCTS
B47: Locally-produced Products
...

Sheet Doanh thu KVF
O1: 1 | P1: 2 | Q1: 3 | R1: 4 | S1: 5 | T1: 6 | U1: 7 | V1: 8 | W1: 9 | X1: 10 | Y1: 11 | Z1: 12 | AA1: 13 | AB1: 14 | AC1: 15 | AD1: 16 | AE1: 17 | AF1: 18 | AG1: 19 | AH1: 20 | AI1: 21 | AJ1: 22 | AK1: 23 | AL1: 24 | AM1: 25 | AN1: 26 | AO1: 27 | AP1: 28 | AQ1: 29 | AR1: 30 | AS1: 31 | AT1: 32 | AU1: 33 | AV1: 34 | AW1: 35 | AX1: 36 | AY1: 37 | AZ1: 38 | BA1: 39 | BB1: 40
Q2: Proj | R2: Proj | S2: Proj | T2: Proj | U2: Proj | V2: Proj | W2: Proj | X2: Proj | Y2: Proj | Z2: Proj | AA2: Proj | AB2: Proj | AC2: Proj | AD2: Proj | AE2: Proj | AF2: Proj | AG2: Proj | AH2: Proj | AI2: Proj | AJ2: Proj | AK2: Proj | AL2: Proj | AM2: Proj | AN2: Proj | AO2: Proj | AP2: Proj | AQ2: Proj | AR2: Proj | AS2: Proj | AT2: Proj | AU2: Proj | AV2: Proj | AW2: Proj | AX2: Proj | AY2: Proj | AZ2: Proj | BA2: Proj | BB2: Proj
D3: 41274 | E3: 41639 | F3: 42004 | G3: 42369 | H3: 42735 | I3: 43100 | J3: 43465 | K3: 43830 | L3: 44196 | M3: 44561 | N3: 44926 | O3: 45291 | P3: 45657 | Q3: 46022 | R3: 46387 | S3: 46752 | T3: 47118 | U3: 47483 | V3: 47848 | W3: 48213 | X3: 48579 | Y3: 48944 | Z3: 49309 | AA3: 49674 | AB3: 50040 | AC3: 48944 | AD3: 49309 | AE3: 49674 | AF3: 50040 | AG3: 50405 | AH3: 50770 | AI3: 51135 | AJ3: 51501 | AK3: 51866 | AL3: 52231 | AM3: 52596 | AN3: 52962 | AO3: 53327 | AP3: 53692 | AQ3: 54057 | AR3: 54423 | AS3: 54788 | AT3: 55153 | AU3: 55518 | AV3: 55884 | AW3: 56249 | AX3: 56614 | AY3: 56979 | AZ3: 57345 | BA3: 57710 | BB3: 58075
B6: REVENUE (price - sale - volume)
A8: 1 | B8: DOANH THU (tỷ đồng)
B9: NPK | P9: =P17*1000*P31*1000*1000/(10^9) -> 1132.9956 | Q9: =Q17*1000*Q31*1000*1000/(10^9) -> 1525.4884 | R9: =R17*1000*R31*1000*1000/(10^9) -> 1725.4452 | S9: =S17*1000*S31*1000*1000/(10^9) -> 2143.003 | T9: =T17*1000*T31*1000*1000/(10^9) -> 2996.1725 | U9: =U17*1000*U31*1000*1000/(10^9) -> 3183.7328 | V9: =V17*1000*V31*1000*1000/(10^9) -> 2986.2403 | W9: =W17*1000*W31*1000*1000/(10^9) -> 3469.4821 | ... Z9: =Z17*1000*Z31*1000*1000/(10^9) -> 4933.018
B10: Tổng | P10: =P9 -> 1132.9956 | Q10: =Q9 -> 1525.4884 | R10: =R9 -> 1725.4452 | S10: =S9 -> 2143.003 | T10: =T9 -> 2996.1725 | U10: =U9 -> 3183.7328 | V10: =V9 -> 2986.2403 | W10: =W9 -> 3469.4821 | ... Z10: =Z9 -> 4933.018
A12: 2 | B12: Growth (1.000 tỷ đồng)
B13: NPK | Q13: =Q9/P9-1 -> 0.34642042 | R13: =R9/Q9-1 -> 0.13107724 | S13: =S9/R9-1 -> 0.242 | T13: =T9/S9-1 -> 0.39811867 | U13: =U9/T9-1 -> 0.0626 | V13: =V9/U9-1 -> -0.062031746 | W13: =W9/V9-1 -> 0.16182278 | X13: =X9/W9-1 -> 0.11384052 | ... Z13: =Z9/Y9-1 -> 0.16422317
B14: Growth
A16: 3 | B16: Giá bán trung bình (vnđ/sp)
B17: NPK (nghìn vnd/kg) | P17: =(720000/50)/1000*0.85 -> 12.24 | Q17: =P17*(1+Q18) -> 13.80141 | R17: =Q17*(1+R18) -> 14.353467 | S17: =R17*(1+S18) -> 15.501744 | T17: =S17*(1+T18) -> 19.222163 | U17: =T17*(1+U18) -> 17.68439 | V17: =U17*(1+V18) -> 16.269639 | W17: =V17*(1+W18) -> 16.595031 | X17: =W17*(1+X18) -> 16.760982 | ... Z17: =Y17*(1+Z18) -> 17.775021
B18: Growth | Q18: ='Doanh thu DCM'!J252 -> 0.12756621 | R18: ='Doanh thu DCM'!K252 -> 0.04 | S18: ='Doanh thu DCM'!L252 -> 0.08 | T18: ='Doanh thu DCM'!M252 -> 0.24 | U18: ='Doanh thu DCM'!N252 -> -0.08 | V18: ='Doanh thu DCM'!O252 -> -0.08 | W18: ='Doanh thu DCM'!P252 -> 0.02 | X18: ='Doanh thu DCM'!Q252 -> 0.01 | ... Z18: ='Doanh thu DCM'!S252 -> 0.05
B19: Tổng
A21: 4 | B21: Tăng trưởng giá bán
B22: NPK | Q22: =Q17/P17-1 -> 0.12756621 | R22: =R17/Q17-1 -> 0.04 | S22: =S17/R17-1 -> 0.08 | T22: =T17/S17-1 -> 0.24 | U22: =U17/T17-1 -> -0.08 | V22: =V17/U17-1 -> -0.08 | W22: =W17/V17-1 -> 0.02 | X22: =X17/W17-1 -> 0.01 | ... Z22: =Z17/Y17-1 -> 0.05
B23: Tổng
A25: 5 | B25: Sản lượng sản xuất
B26: NPK (nghìn tấn) | P26: =94142/1000 -> 94.142 | Q26: =120 -> 120 | R26: =Q26*(1+R27) -> 132 | S26: =R26*(1+S27) -> 145.2 | T26: =S26*(1+T27) -> 159.72 | U26: =T26*(1+U27) -> 175.692 | V26: =U26*(1+V27) -> 193.2612 | W26: =V26*(1+W27) -> 212.58732 | X26: =W26*(1+X27) -> 233.84605 | Y26: =X26*(1+Y27) -> 257.23066 | Z26: =Y26*(1+Z27) -> 282.95372
B27: Growth | Q27: ='Doanh thu DCM'!J246 -> 0.065 | R27: ='Doanh thu DCM'!K246 -> 0.1 | S27: ='Doanh thu DCM'!L246 -> 0.1 | T27: ='Doanh thu DCM'!M246 -> 0.1 | U27: =T27 -> 0.1 | V27: =U27 -> 0.1 | W27: =V27 -> 0.1 | X27: =W27 -> 0.1 | Y27: =X27 -> 0.1 | Z27: =Y27 -> 0.1
B28: Tổng
A30: 5 | B30: Sản lượng tiêu thụ
B31: NPK (nghìn tấn) | P31: =92565/1000 -> 92.565 | Q31: =Q26*Q32 -> 110.53134 | R31: =R26*R32 -> 120.21104 | S31: =S26*S32 -> 138.2427 | T31: =T26*T32 -> 155.87073 | U31: =U26*U32 -> 180.03069 | V31: =V26*V32 -> 183.54682 | W31: =W26*W32 -> 209.06752 | X31: =X26*X32 -> 230.56226 | ... Z31: =Z26*Z32 -> 277.5253
B32: % sản xuất | Q32: ='Doanh thu DCM'!J249 + 5% -> 0.92109452 | R32: ='Doanh thu DCM'!K249 -> 0.91068972 | S32: ='Doanh thu DCM'!L249 -> 0.95208471 | T32: ='Doanh thu DCM'!M249 -> 0.97589986 | U32: ='Doanh thu DCM'!N249 -> 1.0246949 | V32: ='Doanh thu DCM'!O249 -> 0.94973443 | W32: ='Doanh thu DCM'!P249 -> 0.98344305 | X32: ='Doanh thu DCM'!Q249 -> 0.98595744 | Y32: ='Doanh thu DCM'!R249 -> 0.97304497 | Z32: ='Doanh thu DCM'!S249 -> 0.98081516
B33: Growth | Q33: =Q31/P31-1 -> 0.19409434 | R33: =R31/Q31-1 -> 0.087574268 | S33: =S31/R31-1 -> 0.15 | T33: =T31/S31-1 -> 0.12751506 | U33: =U31/T31-1 -> 0.155 | V33: =V31/U31-1 -> 0.019530711 | W33: =W31/V31-1 -> 0.13904195 | X33: =X31/W31-1 -> 0.1028124 | ... Z33: =Z31/Y31-1 -> 0.10878397
B34: Tổng
B36: GVHB
A38: 1 | B38: GVHB
B39: NPK | P39: =(P9-P54) -> 1159.3456 | Q39: =Q9-Q54 -> 1363.0227 | R39: =R9-R54 -> 1541.7329 | S39: =S9-S54 -> 1863.2483 | T39: =T9-T54 -> 2436.8761 | U39: =U9-U54 -> 2567.1285 | V39: =V9-V54 -> 2479.0898 | W39: =W9-W54 -> 2846.3011 | X39: =X9-X54 -> 3116.9463 | ... Z39: =Z9-Z54 -> 3681.7682
B40: Tổng | P40: =P39 -> 1159.3456 | Q40: =Q39 -> 1363.0227 | R40: =R39 -> 1541.7329 | S40: =S39 -> 1863.2483 | T40: =T39 -> 2436.8761 | U40: =U39 -> 2567.1285 | V40: =V39 -> 2479.0898 | W40: =W39 -> 2846.3011 | ... Z40: =Z39 -> 3681.7682
B41: % As Revenue | P41: =P40/P10 -> 1.0232569 | Q41: =Q40/Q10 -> 0.8934992 | R41: =R40/R10 -> 0.89352759 | S41: =S40/S10 -> 0.86945673 | T41: =T40/T10 -> 0.81332972 | U41: =U40/U10 -> 0.80632661 | V41: =V40/V10 -> 0.83017088 | W41: =W40/W10 -> 0.82038212 | ... Z41: =Z40/Z10 -> 0.74635207
A43: 2 | B43: GVHB 01 đơn vị sp
B44: NPK | P44: =P39/P31 -> 12.524665 | Q44: =Q39/Q31 -> 12.331549 | R44: =R39/R31 -> 12.825219 | S44: =S39/S31 -> 13.478096 | T44: =T39/T31 -> 15.633956 | U44: =U39/U31 -> 14.259394 | V44: =V39/V31 -> 13.50658 | W44: =W39/W31 -> 13.614267 | ... Z44: =Z39/Z31 -> 13.266424
B45: Tổng
A47: 3 | B47: Tăng trưởng giá vốn (1.000vnđ/m3)
B48: NPK | Q48: =Q39/P39-1 -> 0.1756828 | R48: =R39/Q39-1 -> 0.13111317 | S48: =S39/R39-1 -> 0.2085416 | T48: =T39/S39-1 -> 0.30786436 | U48: =U39/T39-1 -> 0.053450568 | V48: =V39/U39-1 -> -0.034294641 | W48: =W39/V39-1 -> 0.14812343 | X48: =X39/W39-1 -> 0.095086658 | ... Z48: =Z39/Y39-1 -> 0.13150469
B49: Tổng
B51: LNG
A53: 1 | B53: LNG
B54: NPK | P54: =-26.35 -> -26.35 | Q54: =Q9*Q59 -> 162.46573 | R54: =R9*R59 -> 183.71231 | S54: =S9*S59 -> 279.75462 | T54: =T9*T59 -> 559.29635 | U54: =U9*U59 -> 616.60433 | V54: =V9*V59 -> 507.15057 | W54: =W9*W59 -> 623.18102 | X54: =X9*X59 -> 747.50342 | ... Z54: =Z9*Z59 -> 1251.2498
...

Sheet Welfare & Dividends
B1: =1 -> 1 | K1: Số liệu 2021 chưa có vì chưa tổ chức ĐHCĐTN 2022, sử dụng số kế hoạch của ĐHCĐTN 2021 | Q1: 1 | R1: 2 | S1: 3 | T1: 4 | U1: 5 | V1: 6 | W1: 7 | X1: 8 | Y1: 9 | Z1: 10
N2: =IF(TODAY()<N3,"Proj","") | O2: =IF(TODAY()<O3,"Proj","") | P2: =IF(TODAY()<P3,"Proj","") | Q2: =IF(TODAY()<Q3,"Proj","") -> Proj | R2: =IF(TODAY()<R3,"Proj","") -> Proj | S2: =IF(TODAY()<S3,"Proj","") -> Proj | T2: =IF(TODAY()<T3,"Proj","") -> Proj | U2: =IF(TODAY()<U3,"Proj","") -> Proj | ... Z2: =IF(TODAY()<Z3,"Proj","") -> Proj
B3: WELFARE & DIVIDENDS | D3: 41274 | E3: =DATE(YEAR(D3),MONTH(D3)+13,0) -> 41639 | F3: =DATE(YEAR(E3),MONTH(E3)+13,0) -> 42004 | G3: =DATE(YEAR(F3),MONTH(F3)+13,0) -> 42369 | H3: =DATE(YEAR(G3),MONTH(G3)+13,0) -> 42735 | I3: =DATE(YEAR(H3),MONTH(H3)+13,0) -> 43100 | J3: =DATE(YEAR(I3),MONTH(I3)+13,0) -> 43465 | K3: =DATE(YEAR(J3),MONTH(J3)+13,0) -> 43830 | L3: =DATE(YEAR(K3),MONTH(K3)+13,0) -> 44196 | ... Z3: =DATE(YEAR(Y3),MONTH(Y3)+13,0) -> 49309
A4: 1 | B4: LNST | K4: =Input!K94 -> 427.72373 | L4: =Input!L94 -> 662.44633 | M4: =Input!M94 -> 1826.1243 | N4: =Input!N94 -> 4321.0807 | O4: =Input!O94 -> 1110.1427 | P4: =Input!P94 -> 1428.0066
A5: 2 | B5: Trích lập các quỹ | K5: =K6+K8 -> 143.3679 | L5: =L6+L8 -> 151.68463 | M5: =M6+M8 -> 646.82729 | N5: =N6+N8 -> 1418.8542 | O5: =O6+O8 -> 455.40282 | P5: =P6+P8 -> 550.15197
A6: 2.1 | B6: Quỹ thuộc công ty | K6: =K7 -> 34.217898 | L6: =L7 -> 66.244633 | M6: =M7 -> 547.83729 | N6: =N7 -> 1296.3242 | O6: =O7 -> 333.04282 | P6: =P7 -> 428.40197
B7: + Quỹ ĐTPT | K7: =0.08*K4 -> 34.217898 | L7: =0.1*L4 -> 66.244633 | M7: =0.3*M4 -> 547.83729 | N7: =0.3*N4 -> 1296.3242 | O7: =0.3*O4 -> 333.04282 | P7: =0.3*P4 -> 428.40197
A8: 2.2 | B8: Quỹ chi ra | K8: =K9 -> 109.15 | L8: =L9 -> 85.44 | M8: =M9 -> 98.99 | N8: =N9 -> 122.53 | O8: =O9 -> 122.36 | P8: =P9 -> 121.75
B9: - Quỹ khen thưởng phúc lợi | K9: =SUM(K10:K11) -> 109.15 | L9: =SUM(L10:L11) -> 85.44 | M9: =SUM(M10:M11) -> 98.99 | N9: =SUM(N10:N11) -> 122.53 | O9: =SUM(O10:O11) -> 122.36 | P9: =SUM(P10:P11) -> 121.75
B10: + Quỹ khen thưởng BLĐ, HĐQT, BKS | K10: 1.56 | L10: 2.08 | M10: =2.31 -> 2.31 | N10: =3.12 -> 3.12 | O10: =2.61 -> 2.61 | P10: =2.61 -> 2.61
B11: + Quỹ khen thưởng, phúc lợi người lao động | K11: 107.59 | L11: 83.36 | M11: =96.68 -> 96.68 | N11: =119.41 -> 119.41 | O11: =119.75 -> 119.75 | P11: =119.14 -> 119.14
A12: 3 | B12: Chi cổ tức | K12: =K13+K15 -> 317.64 | L12: =L13+L15 -> 423.52 | M12: =M13+M15 -> 952.92 | N12: =N13+N15 -> 1588.2 | O12: =O13+O15 -> 1058.8 | P12: =P13+P15 -> 1058.8
B13: - Lần 1 | K13: =317.64 -> 317.64 | L13: =423.52 -> 423.52 | M13: =952.92 -> 952.92 | N13: =1588.2 -> 1588.2 | O13: =1058.8 -> 1058.8 | P13: =1058.8 -> 1058.8
B14: % mệnh giá | K14: =600/10000 -> 0.06 | L14: =800/10000 -> 0.08 | M14: =1800/10000 -> 0.18 | N14: =30% -> 0.3 | O14: =20% -> 0.2 | P14: =20% -> 0.2
B15: - Lần 2 | K15: 0 | L15: 0 | M15: 0 | N15: 0 | O15: 0 | P15: 0
B16: % mệnh giá
B17: LNST CPP | K17: =K4-K5-K12 -> -33.284169 | L17: =L4-L5-L12 -> 87.241701 | M17: =M4-M5-M12 -> 226.377 | N17: =N4-N5-N12 -> 1314.0265 | O17: =O4-O5-O12 -> -404.0601 | P17: =P4-P5-P12 -> -180.94539
B19: THE NUMBER OF COMMON SHARE (triệu CP)
A20: 1 | B20: SLCP phát hành đầu năm
A21: 2 | B21: Cổ tức bằng cổ phiếu
A22: 3 | B22: Cổ phiếu thưởng
A23: 4 | B23: Phát hành riêng lẻ/ công khai
B24: - đợt 1
B25: - đợt 2
A26: 5 | B26: ESOP
A27: 6 | B27: SLCP phát hành cuối năm | K27: 529400000 | L27: 529400000 | M27: 529400000 | N27: 529400000 | O27: 529400000 | P27: 529400000
A28: 7 | B28: CP quỹ | K28: ='BS Raw'!F120 -> 0 | L28: ='BS Raw'!G120 -> 0 | M28: ='BS Raw'!H120 -> 0 | N28: ='BS Raw'!I120 -> 0 | O28: ='BS Raw'!J120 -> 0 | P28: ='BS Raw'!K120 -> 0
A29: 8 | B29: SLCP lưu hành | K29: =K27-K28 -> 529400000 | L29: =L27-L28 -> 529400000 | M29: =M27-M28 -> 529400000 | N29: =N27-N28 -> 529400000 | O29: =O27-O28 -> 529400000 | P29: =P27-P28 -> 529400000 | Q29: https://tapchicongthuong.vn/dam-ca-mau--dcm--chot-chia-co-tuc-20--bang-tien--du-bao-gia-phan-bon-co-the-tang-142081.htm

Sheet Consol. Rev.
B1: 1 | N1: 1 | O1: 2 | P1: 3 | Q1: 4 | R1: 5 | S1: 6 | T1: 7 | U1: 8 | V1: 9 | W1: 10 | X1: 11 | Y1: 12 | Z1: 13 | AA1: 14 | AB1: 15 | AC1: 16 | AD1: 17 | AE1: 18 | AF1: 19 | AG1: 20 | AH1: 21 | AI1: 22 | AJ1: 23 | AK1: 24 | AL1: 25 | AM1: 26 | AN1: 27 | AO1: 28 | AP1: 29 | AQ1: 30 | AR1: 31 | AS1: 32 | AT1: 33 | AU1: 34 | AV1: 35 | AW1: 36 | AX1: 37 | AY1: 38 | AZ1: 39 | BA1: 40
C2: =IF(TODAY()<C3,"Proj","") | D2: =IF(TODAY()<D3,"Proj","") | F2: =IF(TODAY()<F3,"Proj","") | G2: =IF(TODAY()<G3,"Proj","") | H2: =IF(TODAY()<H3,"Proj","") | I2: =IF(TODAY()<I3,"Proj","") | J2: =IF(TODAY()<J3,"Proj","") | K2: =IF(TODAY()<K3,"Proj","") | L2: =IF(TODAY()<L3,"Proj","") | M2: =IF(TODAY()<M3,"Proj","") | ... BA2: =IF(TODAY()<BA3,"Proj","") -> Proj
D3: 41274 | E3: =DATE(YEAR(D3),MONTH(D3)+13,0) -> 41639 | F3: =DATE(YEAR(E3),MONTH(E3)+13,0) -> 42004 | G3: =DATE(YEAR(F3),MONTH(F3)+13,0) -> 42369 | H3: =DATE(YEAR(G3),MONTH(G3)+13,0) -> 42735 | I3: =DATE(YEAR(H3),MONTH(H3)+13,0) -> 43100 | J3: =DATE(YEAR(I3),MONTH(I3)+13,0) -> 43465 | K3: =DATE(YEAR(J3),MONTH(J3)+13,0) -> 43830 | L3: =DATE(YEAR(K3),MONTH(K3)+13,0) -> 44196 | ... BA3: =DATE(YEAR(AZ3),MONTH(AZ3)+13,0) -> 59171 | BC3: Notes
H4: % growth rev | L4: =L8/K8-1 -> 0.073592305 | M4: =M8/L8-1 -> 0.30530404 | N4: =N8/M8-1 -> 0.613466 | O4: =O8/N8-1 -> -0.21061755 | P4: =P8/O8-1 -> 0.16053712 | Q4: =Q8/P8-1 -> 0.21581151 | R4: =R8/Q8-1 -> 0.048080581 | S4: =S8/R8-1 -> 0.028293767 | ... Z4: =Z8/Y8-1 -> 0.013457614
B6: REVENUE (price - sale - volume)
B8: Consol. revenue (FC) | K8: ='Doanh thu DCM'!D9+'Doanh thu KVF'!K9 -> 7042.9669 | L8: ='Doanh thu DCM'!E9+'Doanh thu KVF'!L9 -> 7561.2751 | M8: ='Doanh thu DCM'!F9+'Doanh thu KVF'!M9 -> 9869.7629 | N8: ='Doanh thu DCM'!G9+'Doanh thu KVF'!N9 -> 15924.527 | O8: ='Doanh thu DCM'!H9+'Doanh thu KVF'!O9 -> 12570.542 | P8: ='Doanh thu DCM'!I9+'Doanh thu KVF'!P9 -> 14588.581 | Q8: ='Doanh thu DCM'!J9+'Doanh thu KVF'!Q9 -> 17736.964 | R8: ='Doanh thu DCM'!K9+'Doanh thu KVF'!R9 -> 18589.768 | ... Z8: ='Doanh thu DCM'!S9+'Doanh thu KVF'!Z9 -> 22829.84
B9: Mảng Ure | K9: ='Doanh thu DCM'!D112 -> 5467.6613 | L9: ='Doanh thu DCM'!E112 -> 5950.9514 | M9: ='Doanh thu DCM'!F112 -> 7122.7848 | N9: ='Doanh thu DCM'!G112 -> 12056.911 | O9: ='Doanh thu DCM'!H112 -> 8067.79 | P9: ='Doanh thu DCM'!I112 -> 7432.0335 | Q9: ='Doanh thu DCM'!J112 -> 9638.5364 | R9: ='Doanh thu DCM'!K112 -> 10016.532 | ... Z9: ='Doanh thu DCM'!S112 -> 11083.615
B10: Mảng NPK | K10: ='Doanh thu DCM'!D241+'Doanh thu KVF'!K9 -> 0 | L10: ='Doanh thu DCM'!E241+'Doanh thu KVF'!L9 -> 0 | M10: ='Doanh thu DCM'!F241+'Doanh thu KVF'!M9 -> 391.24903 | N10: ='Doanh thu DCM'!G241+'Doanh thu KVF'!N9 -> 1253.322 | O10: ='Doanh thu DCM'!H241+'Doanh thu KVF'!O9 -> 1675.6449 | P10: ='Doanh thu DCM'!I241+'Doanh thu KVF'!P9+'Doanh thu DCM'!V248 -> 3928.8546 | Q10: ='Doanh thu DCM'!J241+'Doanh thu KVF'!Q9 -> 4011.5978 | R10: ='Doanh thu DCM'!K241+'Doanh thu KVF'!R9 -> 4569.5543 | S10: ='Doanh thu DCM'!L241+'Doanh thu KVF'!S9 -> 5521.8046 | T10: ='Doanh thu DCM'!M241+'Doanh thu KVF'!T9 -> 7696.7645 | U10: ='Doanh thu DCM'!N241+'Doanh thu KVF'!U9 -> 7508.2775 | V10: ='Doanh thu DCM'!O241+'Doanh thu KVF'!V9 -> 6964.8214 | W10: ='Doanh thu DCM'!P241+'Doanh thu KVF'!W9 -> 7527.6348 | X10: ='Doanh thu DCM'!Q241+'Doanh thu KVF'!X9 -> 7963.1839 | ... Z10: ='Doanh thu DCM'!S241+'Doanh thu KVF'!Z9 -> 9279.7257 | AC10: ='Doanh thu KVF'!AC10 -> 0 | AD10: ='Doanh thu KVF'!AD10 -> 0 | AE10: ='Doanh thu KVF'!AE10 -> 0 | AF10: ='Doanh thu KVF'!AF10 -> 0 | AG10: ='Doanh thu KVF'!AG10 -> 0 | AH10: ='Doanh thu KVF'!AH10 -> 0 | AI10: ='Doanh thu KVF'!AI10 -> 0 | AJ10: ='Doanh thu KVF'!AJ10 -> 0 | ... AX10: ='Doanh thu KVF'!AX10 -> 0
B11: Mảng NH3 | K11: ='Doanh thu DCM'!D170 -> 38.074579 | L11: ='Doanh thu DCM'!E170 -> 0 | M11: ='Doanh thu DCM'!F170 -> 24.014973 | N11: ='Doanh thu DCM'!G170 -> 98.512861 | O11: ='Doanh thu DCM'!H170 -> 39.608264 | P11: ='Doanh thu DCM'!I170 -> 47.733036 | Q11: ='Doanh thu DCM'!J170 -> 45.701843 | R11: ='Doanh thu DCM'!K170 -> 44.787806 | ... Z11: ='Doanh thu DCM'!S170 -> 39.683034
B12: Mảng tự doanh | K12: ='Doanh thu DCM'!D159 -> 1311.8823 | L12: ='Doanh thu DCM'!E159 -> 1331.3239 | M12: ='Doanh thu DCM'!F159 -> 1638.1589 | N12: ='Doanh thu DCM'!G159 -> 1972.7754 | O12: ='Doanh thu DCM'!H159 -> 2167.4294 | P12: ='Doanh thu DCM'!I159 -> 2439.9787 | Q12: ='Doanh thu DCM'!J159 -> 3159.7159 | R12: ='Doanh thu DCM'!K159 -> 2965.1725 | ... Z12: ='Doanh thu DCM'!S159 -> 855.50378
B13: Mảng dịch vụ | K13: ='Doanh thu DCM'!D194 -> 225.34878 | L13: ='Doanh thu DCM'!E194 -> 278.9998 | M13: ='Doanh thu DCM'!F194 -> 693.55519 | N13: ='Doanh thu DCM'!G194 -> 543.00515 | O13: ='Doanh thu DCM'!H194 -> 620.0695 | P13: ='Doanh thu DCM'!I194 -> 739.98096 | Q13: ='Doanh thu DCM'!J194 -> 881.41248 | R13: ='Doanh thu DCM'!K194 -> 993.72123 | ... Z13: ='Doanh thu DCM'!S194 -> 1571.3125
B14: Consol. revenue | K14: =SUM(K9:K13) -> 7042.9669 | L14: =SUM(L9:L13) -> 7561.2751 | M14: =SUM(M9:M13) -> 9869.7629 | N14: =SUM(N9:N13) -> 15924.527 | O14: =SUM(O9:O13) -> 12570.542 | P14: =SUM(P9:P13) -> 14588.581 | Q14: =SUM(Q9:Q13) -> 17736.964 | R14: =SUM(R9:R13) -> 18589.768 | ... Z14: =SUM(Z9:Z13) -> 22829.84
B15: Đối chiếu | K15: =K8-K14 -> 0 | L15: =L8-L14 -> 0 | M15: =M8-M14 -> 0 | N15: =N8-N14 -> 0 | O15: =O8-O14 -> 0 | P15: =P8-P14 -> 0 | Q15: =Q8-Q14 -> 0 | R15: =R8-R14 -> 0 | ... Z15: =Z8-Z14 -> 0
B17: Rev. Growth (FC) | D17: =IFERROR(D8/C8-1," ") | E17: =IFERROR(E8/D8-1," ") | F17: =IFERROR(F8/E8-1," ") | G17: =IFERROR(G8/F8-1," ") | H17: =IFERROR(H8/G8-1," ") | I17: =IFERROR(I8/H8-1," ")
B18: Mảng Ure | D18: =IFERROR(D9/C9-1," ") | E18: =IFERROR(E9/D9-1," ") | F18: =IFERROR(F9/E9-1," ") | G18: =IFERROR(G9/F9-1," ") | H18: =IFERROR(H9/G9-1," ") | I18: =IFERROR(I9/H9-1," ") | L18: =IFERROR(L9/K9-1, 0) -> 0.088390646 | M18: =IFERROR(M9/L9-1, 0) -> 0.1969153 | N18: =IFERROR(N9/M9-1, 0) -> 0.69272438 | O18: =IFERROR(O9/N9-1, 0) -> -0.33085766 | P18: =IFERROR(P9/O9-1, 0) -> -0.078801822 | Q18: =IFERROR(Q9/P9-1, 0) -> 0.29689088 | R18: =IFERROR(R9/Q9-1, 0) -> 0.039217117 | S18: =IFERROR(S9/R9-1, 0) -> -0.01123027 | ... Z18: =IFERROR(Z9/Y9-1, 0) -> -0.050326239
B19: Mảng NPK | D19: =IFERROR(D10/C10-1," ") | E19: =IFERROR(E10/D10-1," ") | F19: =IFERROR(F10/E10-1," ") | G19: =IFERROR(G10/F10-1," ") | H19: =IFERROR(H10/G10-1," ") | I19: =IFERROR(I10/H10-1," ") | L19: =IFERROR(L10/K10-1, 0) -> 0 | M19: =IFERROR(M10/L10-1, 0) -> 0 | N19: =IFERROR(N10/M10-1, 0) -> 2.2033868 | O19: =IFERROR(O10/N10-1, 0) -> 0.33696288 | P19: =IFERROR(P10/O10-1, 0) -> 1.344682 | Q19: =IFERROR(Q10/P10-1, 0) -> 0.021060383 | R19: =IFERROR(R10/Q10-1, 0) -> 0.13908587 | S19: =IFERROR(S10/R10-1, 0) -> 0.20839018 | ... Z19: =IFERROR(Z10/Y10-1, 0) -> 0.107776
B20: Mảng NH3 | L20: =IFERROR(L11/K11-1, 0) -> -1 | M20: =IFERROR(M11/L11-1, 0) -> 0 | N20: =IFERROR(N11/M11-1, 0) -> 3.1021433 | O20: =IFERROR(O11/N11-1, 0) -> -0.59793814 | P20: =IFERROR(P11/O11-1, 0) -> 0.20512821 | Q20: =IFERROR(Q11/P11-1, 0) -> -0.042553191 | R20: =IFERROR(R11/Q11-1, 0) -> -0.02 | S20: =IFERROR(S11/R11-1, 0) -> -0.02 | ... Z20: =IFERROR(Z11/Y11-1, 0) -> -0.01
B21: Mảng tự doanh | L21: =IFERROR(L12/K12-1, 0) -> 0.014819634 | M21: =IFERROR(M12/L12-1, 0) -> 0.23047361 | N21: =IFERROR(N12/M12-1, 0) -> 0.20426374 | O21: =IFERROR(O12/N12-1, 0) -> 0.098670103 | P21: =IFERROR(P12/O12-1, 0) -> 0.12574773 | Q21: =IFERROR(Q12/P12-1, 0) -> 0.29497683 | R21: =IFERROR(R12/Q12-1, 0) -> -0.061569881 | S21: =IFERROR(S12/R12-1, 0) -> -0.12687326 | ... Z21: =IFERROR(Z12/Y12-1, 0) -> -0.1735
B22: Mảng dịch vụ | L22: =IFERROR(L13/K13-1, 0) -> 0.23807994 | M22: =IFERROR(M13/L13-1, 0) -> 1.4858627 | N22: =IFERROR(N13/M13-1, 0) -> -0.21707002 | O22: =IFERROR(O13/N13-1, 0) -> 0.14192195 | P22: =IFERROR(P13/O13-1, 0) -> 0.19338389 | Q22: =IFERROR(Q13/P13-1, 0) -> 0.1911286 | R22: =IFERROR(R13/Q13-1, 0) -> 0.12741906 | S22: =IFERROR(S13/R13-1, 0) -> 0.063709532 | ... Z22: =IFERROR(Z13/Y13-1, 0) -> 0.11945537
B23: Rev. Growth | D23: =IFERROR(D14/C14-1," ") | E23: =IFERROR(E14/D14-1," ") | F23: =IFERROR(F14/E14-1," ") | G23: =IFERROR(G14/F14-1," ") | H23: =IFERROR(H14/G14-1," ") | I23: =IFERROR(I14/H14-1," ") | L23: =IFERROR(L14/K14-1, 0) -> 0.073592305 | M23: =IFERROR(M14/L14-1, 0) -> 0.30530404 | N23: =IFERROR(N14/M14-1, 0) -> 0.613466 | O23: =IFERROR(O14/N14-1, 0) -> -0.21061755 | P23: =IFERROR(P14/O14-1, 0) -> 0.16053712 | Q23: =IFERROR(Q14/P14-1, 0) -> 0.21581151 | R23: =IFERROR(R14/Q14-1, 0) -> 0.048080581 | S23: =IFERROR(S14/R14-1, 0) -> 0.028293767 | ... Z23: =IFERROR(Z14/Y14-1, 0) -> 0.013457614
B26: COGS
B28: COGS (FC) (Cách 1: theo từng mảng)
B29: % As Revenue | K29: ='Doanh thu DCM'!D11+'Doanh thu KVF'!K39 -> 6083.7747 | L29: ='Doanh thu DCM'!E11+'Doanh thu KVF'!L39 -> 6244.4273 | M29: ='Doanh thu DCM'!F11+'Doanh thu KVF'!M39 -> 7088.826 | N29: ='Doanh thu DCM'!G11+'Doanh thu KVF'!N39 -> 10221.097 | O29: ='Doanh thu DCM'!H11+'Doanh thu KVF'!O39 -> 10538.742 | P29: ='Doanh thu DCM'!I11+'Doanh thu KVF'!P39 -> 12101.446 | Q29: ='Doanh thu DCM'!J11+'Doanh thu KVF'!Q39 -> 13918.244 | R29: ='Doanh thu DCM'!K11+'Doanh thu KVF'!R39 -> 14383.611 | ... Z29: ='Doanh thu DCM'!S11+'Doanh thu KVF'!Z39 -> 16800.955 | AC29: =AC28/AC8 -> #DIV/0! | AD29: =AD28/AD8 -> #DIV/0! | AE29: =AE28/AE8 -> #DIV/0! | AF29: =AF28/AF8 -> #DIV/0! | AG29: =AG28/AG8 -> #DIV/0! | AH29: =AH28/AH8 -> #DIV/0! | AI29: =AI28/AI8 -> #DIV/0! | AJ29: =AJ28/AJ8 -> #DIV/0! | ... AX29: =AX28/AX8 -> #DIV/0!
B30: Mảng Ure | K30: ='Doanh thu DCM'!D115 -> 4728.6086 | L30: ='Doanh thu DCM'!E115 -> 4868.626 | M30: ='Doanh thu DCM'!F115 -> 4786.0641 | N30: ='Doanh thu DCM'!G115 -> 6654.1614 | O30: ='Doanh thu DCM'!H115 -> 6433.0559 | P30: ='Doanh thu DCM'!I115 -> 5498.2702 | Q30: ='Doanh thu DCM'!J115 -> 6918.3945 | R30: ='Doanh thu DCM'!K115 -> 6909.4822 | ... Z30: ='Doanh thu DCM'!S115 -> 7995.8431 | AC30: =#REF! -> #REF! | AD30: =#REF! -> #REF! | AE30: =#REF! -> #REF! | AF30: =#REF! -> #REF! | AG30: =#REF! -> #REF! | AH30: =#REF! -> #REF! | AI30: =#REF! -> #REF! | AJ30: =#REF! -> #REF! | ... AX30: =#REF! -> #REF!
B31: Mảng NPK | K31: ='Doanh thu DCM'!D255+'Doanh thu KVF'!K39 -> 0 | L31: ='Doanh thu DCM'!E255+'Doanh thu KVF'!L39 -> 0 | M31: ='Doanh thu DCM'!F255+'Doanh thu KVF'!M39 -> 392.88368 | N31: ='Doanh thu DCM'!G255+'Doanh thu KVF'!N39 -> 1192.0004 | O31: ='Doanh thu DCM'!H255+'Doanh thu KVF'!O39 -> 1458.8394 | P31: ='Doanh thu DCM'!I255+'Doanh thu KVF'!P39+'Doanh thu DCM'!V251 -> 3731.8756 | Q31: ='Doanh thu DCM'!J255+'Doanh thu KVF'!Q39 -> 3372.5413 | R31: ='Doanh thu DCM'!K255+'Doanh thu KVF'!R39 -> 3931.6133 | S31: ='Doanh thu DCM'!L255+'Doanh thu KVF'!S39 -> 4492.2143 | T31: ='Doanh thu DCM'!M255+'Doanh thu KVF'!T39 -> 5645.7847 | U31: ='Doanh thu DCM'!N255+'Doanh thu KVF'!U39 -> 5635.3493 | V31: ='Doanh thu DCM'!O255+'Doanh thu KVF'!V39 -> 5444.1524 | W31: ='Doanh thu DCM'!P255+'Doanh thu KVF'!W39 -> 5956.8619 | X31: ='Doanh thu DCM'!Q255+'Doanh thu KVF'!X39 -> 6185.0129 | ... Z31: ='Doanh thu DCM'!S255+'Doanh thu KVF'!Z39 -> 6925.9424
B32: Mảng NH3 | K32: ='Doanh thu DCM'!D175 -> 48.754894 | L32: ='Doanh thu DCM'!E175 -> 0 | M32: ='Doanh thu DCM'!F175 -> 13.466274 | N32: ='Doanh thu DCM'!G175 -> 59.107717 | O32: ='Doanh thu DCM'!H175 -> 23.764958 | P32: ='Doanh thu DCM'!I175 -> 28.639822 | Q32: ='Doanh thu DCM'!J175 -> 27.421106 | R32: ='Doanh thu DCM'!K175 -> 26.872684 | ... Z32: ='Doanh thu DCM'!S175 -> 23.80982
B33: Mảng tự doanh | K33: ='Doanh thu DCM'!D165 -> 1185.3326 | L33: ='Doanh thu DCM'!E165 -> 1232.7444 | M33: ='Doanh thu DCM'!F165 -> 1483.9804 | N33: ='Doanh thu DCM'!G165 -> 1876.0864 | O33: ='Doanh thu DCM'!H165 -> 2023.8157 | P33: ='Doanh thu DCM'!I165 -> 2289.6186 | Q33: ='Doanh thu DCM'!J165 -> 2938.8273 | R33: ='Doanh thu DCM'!K165 -> 2770.3519 | ... Z33: ='Doanh thu DCM'!S165 -> 806.90096
B34: Mảng dịch vụ | K34: ='Doanh thu DCM'!D197 -> 121.07868 | L34: ='Doanh thu DCM'!E197 -> 143.05688 | M34: ='Doanh thu DCM'!F197 -> 412.43157 | N34: ='Doanh thu DCM'!G197 -> 439.74153 | O34: ='Doanh thu DCM'!H197 -> 599.26648 | P34: ='Doanh thu DCM'!I197 -> 553.04217 | Q34: ='Doanh thu DCM'!J197 -> 661.05936 | R34: ='Doanh thu DCM'!K197 -> 745.29092 | ... Z34: ='Doanh thu DCM'!S197 -> 1048.4583
B35: COGS Cách 1: theo từng mảng) | K35: =SUM(K30:K34) -> 6083.7747 | L35: =SUM(L30:L34) -> 6244.4273 | M35: =SUM(M30:M34) -> 7088.826 | N35: =SUM(N30:N34) -> 10221.097 | O35: =SUM(O30:O34) -> 10538.742 | P35: =SUM(P30:P34) -> 12101.446 | Q35: =SUM(Q30:Q34) -> 13918.244 | R35: =SUM(R30:R34) -> 14383.611 | ... Z35: =SUM(Z30:Z34) -> 16800.955
K36: =K29-K35 -> 0 | L36: =L29-L35 -> 0 | M36: =M29-M35 -> 0 | N36: =N29-N35 -> 0 | O36: =O29-O35 -> 0 | P36: =P29-P35 -> 0 | Q36: =Q29-Q35 -> 0 | R36: =R29-R35 -> 0 | ... Z36: =Z29-Z35 -> 0
B37: % As Revenue | D37: =IFERROR(D35/D14," ") | E37: =IFERROR(E35/E14," ") | K37: =K35/K14 -> 0.8638085 | L37: =L35/L14 -> 0.82584316 | M37: =M35/M14 -> 0.7182367 | N37: =N35/N14 -> 0.64184622 | O37: =O35/O14 -> 0.83836817 | P37: =P35/P14 -> 0.829515 | Q37: =Q35/Q14 -> 0.78470269 | R37: =R35/R14 -> 0.77373807 | ... Z37: =Z35/Z14 -> 0.73592083 | AC37: =AC35/AC14 -> #DIV/0! | AD37: =AD35/AD14 -> #DIV/0! | AE37: =AE35/AE14 -> #DIV/0! | AF37: =AF35/AF14 -> #DIV/0! | AG37: =AG35/AG14 -> #DIV/0! | AH37: =AH35/AH14 -> #DIV/0! | AI37: =AI35/AI14 -> #DIV/0! | AJ37: =AJ35/AJ14 -> #DIV/0! | ... AX37: =AX35/AX14 -> #DIV/0!
B40: % sai số | K40: =K41/K29 -> 0.13510338 | L40: =L41/L29 -> 0.22294377 | M40: =M41/M29 -> 0.0022809497 | N40: =N41/N29 -> 0.074917532 | O40: =O41/O29 -> 0.14573987 | P40: =P41/P29 -> 0.17374204 | Q40: =Q41/Q29 -> 0.22319632 | R40: =R41/R29 -> 0.20813913 | ... Z40: =Z41/Z29 -> 0.18423995
B41: sai số | K41: =K29-K42 -> 821.93851 | L41: =L29-L42 -> 1392.1562 | M41: =M29-M42 -> 16.169255 | N41: =N29-N42 -> 765.73939 | O41: =O29-O42 -> 1535.915 | P41: =P29-P42 -> 2102.53 | Q41: =Q29-Q42 -> 3106.5007 | R41: =R29-R42 -> 2993.7923 | ... Z41: =Z29-Z42 -> 3095.4071
B42: COGS (FC) (Cách 2: theo chi phí) | K42: =SUM(K44:K48) -> 5261.8362 | L42: =SUM(L44:L48) -> 4852.2711 | M42: =SUM(M44:M48) -> 7072.6567 | N42: =SUM(N44:N48) -> 9455.358 | O42: =SUM(O44:O48) -> 9002.8274 | P42: =SUM(P44:P48) -> 9998.9165 | Q42: =SUM(Q44:Q48) -> 10811.743 | R42: =SUM(R44:R48) -> 11389.819 | ... Z42: =SUM(Z44:Z48) -> 13705.548
B43: % As Revenue | K43: =K42/K14 -> 0.74710506 | L43: =L42/L14 -> 0.64172657 | M43: =M42/M14 -> 0.71659844 | N43: =N42/N14 -> 0.59376069 | O43: =O42/O14 -> 0.7161845 | P43: =P42/P14 -> 0.68539337 | Q43: =Q42/Q14 -> 0.60955994 | R43: =R42/R14 -> 0.6126929 | ... Z43: =Z42/Z14 -> 0.60033481
B44: Chi phí nguyên liệu, vật liệu | K44: =K144 -> 3218.7692 | L44: =L144 -> 2729.9096 | M44: =M144 -> 4548.9811 | N44: =N144 -> 6495.9937 | O44: =O144 -> 6599.137 | P44: =P144 -> 7793.3568 | Q44: =Q144 -> 8117.7933 | R44: =R144 -> 8510.1391 | ... Z44: =Z144 -> 10918.227
B45: Chi phí nhân công | K45: =K146-K127-K103 -> 313.91059 | L45: =L146-L127-L103 -> 293.36237 | M45: =M146-M127-M103 -> 384.54388 | N45: =N146-N127-N103 -> 404.54535 | O45: =O146-O127-O103 -> 436.76978 | P45: =P146-P127-P103 -> 416.96254 | Q45: =Q146-Q127-Q103 -> 623.93159 | R45: =R146-R127-R103 -> 624.82558 | ... Z45: =Z146-Z127-Z103 -> 743.01708
B46: Chi phí khấu hao tài sản cố định | K46: =K148-K129-K113 -> 1299.2003 | L46: =L148-L129-L113 -> 1298.0551 | M46: =M148-M129-M113 -> 1361.6458 | N46: =N148-N129-N113 -> 1381.7351 | O46: =O148-O129-O113 -> 1062.4147 | P46: =P148-P129-P113 -> 724.30755 | Q46: =Q148-Q129-Q113 -> 827.54801 | R46: =R148-R129-R113 -> 919.46118 | ... Z46: =Z148-Z129-Z113 -> 401.3662
B47: Chi phí dịch vụ mua ngoài | K47: =K150-K133-K117 -> 331.50559 | L47: =L150-L133-L117 -> 361.98153 | M47: =M150-M133-M117 -> 317.31392 | N47: =N150-N133-N117 -> 703.79278 | O47: =O150-O133-O117 -> 805.77911 | P47: =P150-P133-P117 -> 965.87478 | Q47: =Q150-Q133-Q117 -> 866.98351 | R47: =R150-R133-R117 -> 919.57246 | ... Z47: =Z150-Z133-Z117 -> 1220.2565
B48: Chi phí khác bằng tiền | K48: =K152-K135-K115-K111-K107 -> 98.450481 | L48: =L152-L135-L115-L111-L107 -> 168.96258 | M48: =M152-M135-M115-M111-M107 -> 460.17202 | N48: =N152-N135-N115-N111-N107 -> 469.29106 | O48: =O152-O135-O115-O111-O107 -> 98.726863 | P48: =P152-P135-P115-P111-P107 -> 98.414876 | Q48: =Q152-Q135-Q115-Q111-Q107 -> 375.48653 | R48: =R152-R135-R115-R111-R107 -> 415.82049 | ... Z48: =Z152-Z135-Z115-Z111-Z107 -> 422.68058
...

Sheet Debt
B1: =1 -> 1 | C1: THÔNG TIN KHOẢN VAY | R1: DỰ PHÓNG KHOẢN VAY
I2: Phân bổ cho các nhà máy | S2: 1 | T2: 2 | U2: 3 | V2: 4 | W2: 5 | X2: 6 | Y2: 7 | Z2: 8 | AA2: 9 | AB2: 10 | AC2: 11 | AD2: 12 | AE2: 13 | AF2: 14 | AG2: 15 | AH2: 16 | AI2: 17 | AJ2: 18 | AK2: 19 | AL2: 20 | AM2: 21 | AN2: 22 | AO2: 23 | AP2: 24 | AQ2: 25 | AR2: 26 | AS2: 27 | AT2: 28 | AU2: 29 | AV2: 30 | AW2: 31 | AX2: 32 | AY2: 33 | AZ2: 34 | BA2: 35 | BB2: 36 | BC2: 37 | BD2: 38 | BE2: 39 | BF2: 40
R3: =IF(TODAY()<R4,"Proj","") | S3: =IF(TODAY()<S4,"Proj","") -> Proj | T3: =IF(TODAY()<T4,"Proj","") -> Proj | U3: =IF(TODAY()<U4,"Proj","") -> Proj | V3: =IF(TODAY()<V4,"Proj","") -> Proj | W3: =IF(TODAY()<W4,"Proj","") -> Proj | X3: =IF(TODAY()<X4,"Proj","") -> Proj | Y3: =IF(TODAY()<Y4,"Proj","") -> Proj | ... BF3: =IF(TODAY()<BF4,"Proj","") -> Proj
B4: Debt | C4: Gốc vay | D4: Thời điểm vay | E4: Kỳ hạn (tháng) | F4: Lãi suất năm | G4: Loại lãi suất | H4: Kỳ điều chỉnh | R4: 45657 | S4: =DATE(YEAR(R4),MONTH(R4)+13,0) -> 46022 | T4: =DATE(YEAR(S4),MONTH(S4)+13,0) -> 46387 | U4: =DATE(YEAR(T4),MONTH(T4)+13,0) -> 46752 | V4: =DATE(YEAR(U4),MONTH(U4)+13,0) -> 47118 | W4: =DATE(YEAR(V4),MONTH(V4)+13,0) -> 47483 | X4: =DATE(YEAR(W4),MONTH(W4)+13,0) -> 47848 | Y4: =DATE(YEAR(X4),MONTH(X4)+13,0) -> 48213 | Z4: =DATE(YEAR(Y4),MONTH(Y4)+13,0) -> 48579 | ... BF4: =DATE(YEAR(BE4),MONTH(BE4)+13,0) -> 60267 | BH4: Notes
B6: ƯỚC TÍNH LÃI SUẤT NGÂN HÀNG
B7: Tổng nợ vay ngân hàng ngắn và dài hạn | BH7: Chênh lệch nợ vay dài và ngắn hạn | BI7: 0.017
B8: Dư nợ gốc đầu năm | R8: =IF(ISTEXT('BS Raw'!J11),('BS Raw'!J92+'BS Raw'!J105)/Debt!$B$1,R17+R24) -> 848.77029 | S8: =IF(ISTEXT('BS Raw'!K11),('BS Raw'!K92+'BS Raw'!K105)/Debt!$B$1,S17+S24) -> 1348.7555 | T8: =IF(ISTEXT('BS Raw'!L11),('BS Raw'!L92+'BS Raw'!L105)/Debt!$B$1,T17+T24) -> 1978.8247 | U8: =IF(ISTEXT('BS Raw'!M11),('BS Raw'!M92+'BS Raw'!M105)/Debt!$B$1,U17+U24) -> 2182.4561 | V8: =IF(ISTEXT('BS Raw'!N11),('BS Raw'!N92+'BS Raw'!N105)/Debt!$B$1,V17+V24) -> 2134.2635 | W8: =IF(ISTEXT('BS Raw'!O11),('BS Raw'!O92+'BS Raw'!O105)/Debt!$B$1,W17+W24) -> 2951.1765 | X8: =IF(ISTEXT('BS Raw'!P11),('BS Raw'!P92+'BS Raw'!P105)/Debt!$B$1,X17+X24) -> 2865.6917 | Y8: =IF(ISTEXT('BS Raw'!Q11),('BS Raw'!Q92+'BS Raw'!Q105)/Debt!$B$1,Y17+Y24) -> 2620.8254 | ... AB8: =IF(ISTEXT('BS Raw'!T11),('BS Raw'!T92+'BS Raw'!T105)/Debt!$B$1,AB17+AB24) -> 2705.5746
B9: + Trả nợ gốc hàng năm
B10: + Vay mới trong năm
B11: Dư nợ gốc cuối năm | R11: =IF(ISTEXT('BS Raw'!K11),('BS Raw'!K92+'BS Raw'!K105)/Debt!$B$1,R20+R27) -> 1348.7555 | S11: =IF(ISTEXT('BS Raw'!L11),('BS Raw'!L92+'BS Raw'!L105)/Debt!$B$1,S17+S24) -> 1348.7555 | T11: =IF(ISTEXT('BS Raw'!M11),('BS Raw'!M92+'BS Raw'!M105)/Debt!$B$1,T17+T24) -> 1978.8247 | U11: =IF(ISTEXT('BS Raw'!N11),('BS Raw'!N92+'BS Raw'!N105)/Debt!$B$1,U17+U24) -> 2182.4561 | V11: =IF(ISTEXT('BS Raw'!O11),('BS Raw'!O92+'BS Raw'!O105)/Debt!$B$1,V17+V24) -> 2134.2635 | W11: =IF(ISTEXT('BS Raw'!P11),('BS Raw'!P92+'BS Raw'!P105)/Debt!$B$1,W17+W24) -> 2951.1765 | X11: =IF(ISTEXT('BS Raw'!Q11),('BS Raw'!Q92+'BS Raw'!Q105)/Debt!$B$1,X17+X24) -> 2865.6917 | Y11: =IF(ISTEXT('BS Raw'!R11),('BS Raw'!R92+'BS Raw'!R105)/Debt!$B$1,Y17+Y24) -> 2620.8254 | Z11: =IF(ISTEXT('BS Raw'!S11),('BS Raw'!S92+'BS Raw'!S105)/Debt!$B$1,Z17+Z24) -> 2551.4777 | ... AB11: =IF(ISTEXT('BS Raw'!U11),('BS Raw'!U92+'BS Raw'!U105)/Debt!$B$1,AB17+AB24) -> 2705.5746
B12: + Lãi vay hàng năm | R12: =Notes!K158/Debt!$B$1 -> 44.380805
B13: + Lãi suất chung ước tính | R13: =IFERROR(R12/AVERAGE(R8,R11),0) + 0 -> 0.040391612 | S13: =IF(S12="",R13,S12/AVERAGE(S8,S11)) -> 0.040391612 | T13: =IF(T12="",S13,T12/AVERAGE(T8,T11)) -> 0.040391612 | U13: =IF(U12="",T13,U12/AVERAGE(U8,U11)) -> 0.040391612 | V13: =IF(V12="",U13,V12/AVERAGE(V8,V11)) -> 0.040391612 | W13: =IF(W12="",V13,W12/AVERAGE(W8,W11)) -> 0.040391612 | X13: =IF(X12="",W13,X12/AVERAGE(X8,X11)) -> 0.040391612 | Y13: =IF(Y12="",X13,Y12/AVERAGE(Y8,Y11)) -> 0.040391612 | Z13: =IF(Z12="",Y13,Z12/AVERAGE(Z8,Z11)) -> 0.040391612 | ... AB13: =IF(AB12="",AA13,AB12/AVERAGE(AB8,AB11)) -> 0.040391612
B15: TỔNG HỢP NỢ VAY
A16: 1 | B16: Vay ngắn hạn ngân hàng
B17: Dư nợ gốc đầu năm | R17: =R43 -> 845.80581 | S17: =S43 -> 1229.228 | T17: =T43 -> 1627.7236 | U17: =U43 -> 1685.448 | V17: =V43 -> 1550.5483 | W17: =W43 -> 2136.8592 | X17: =X43 -> 2154.1676 | Y17: =Y43 -> 2045.1654 | ... AB17: =AB43 -> 2367.7131
B18: + Trả nợ gốc hàng năm
B19: + Vay mới trong năm
B20: Dư nợ gốc cuối năm | R20: =R46 -> 1229.228 | S20: =S46 -> 1627.7236 | T20: =T46 -> 1685.448 | U20: =U46 -> 1550.5483 | V20: =V46 -> 2136.8592 | W20: =W46 -> 2154.1676 | X20: =X46 -> 2045.1654 | Y20: =Y46 -> 2106.1436 | ... AB20: =AB46 -> 2492.9776
B21: + Lãi vay hàng năm | R21: =+R48 -> 40.923836 | S21: =+S48 -> 53.461651 | T21: =+T48 -> 60.877171 | U21: =+U48 -> 58.543259 | V21: =+V48 -> 64.204686 | W21: =+W48 -> 77.231774 | X21: =+X48 -> 76.792497 | Y21: =+Y48 -> 76.965831 | ... AB21: =+AB48 -> 92.953407
A23: 2 | B23: Vay dài hạn ngân hàng
B24: Dư nợ gốc đầu năm | R24: =R54 -> 2.9644799 | S24: =+S54+S104+S151+S162+S173+S184+S195+S206+S217+S228+S239 -> 119.5275 | T24: =+T54+T104+T151+T162+T173+T184+T195+T206+T217+T228+T239 -> 351.10114 | U24: =+U54+U104+U151+U162+U173+U184+U195+U206+U217+U228+U239 -> 497.00808 | V24: =+V54+V104+V151+V162+V173+V184+V195+V206+V217+V228+V239 -> 583.71521 | W24: =+W54+W104+W151+W162+W173+W184+W195+W206+W217+W228+W239 -> 814.31731 | X24: =+X54+X104+X151+X162+X173+X184+X195+X206+X217+X228+X239 -> 711.52402 | Y24: =+Y54+Y104+Y151+Y162+Y173+Y184+Y195+Y206+Y217+Y228+Y239 -> 575.66 | Z24: =+Z54+Z104+Z151+Z162+Z173+Z184+Z195+Z206+Z217+Z228+Z239 -> 445.33407 | ... AB24: =+AB54+AB104+AB151+AB162+AB173+AB184+AB195+AB206+AB217+AB228+AB239 -> 337.86153
B25: + Trả nợ gốc hàng năm | S25: =+S55+S106+S153+S164+S175+S186+S197+S208+S219+S230+S241 -> 100.1572 | T25: =+T55+T106+T153+T164+T175+T186+T197+T208+T219+T230+T241 -> 154.83812 | U25: =+U55+U106+U153+U164+U175+U186+U197+U208+U219+U230+U241 -> 208.51484 | V25: =+V55+V106+V153+V164+V175+V186+V197+V208+V219+V230+V241 -> 257.39999 | W25: =+W55+W106+W153+W164+W175+W186+W197+W208+W219+W230+W241 -> 291.75704 | X25: =+X55+X106+X153+X164+X175+X186+X197+X208+X219+X230+X241 -> 289.54095 | Y25: =+Y55+Y106+Y153+Y164+Y175+Y186+Y197+Y208+Y219+Y230+Y241 -> 254.64696 | Z25: =+Z55+Z106+Z153+Z164+Z175+Z186+Z197+Z208+Z219+Z230+Z241 -> 225.75525 | ... AB25: =+AB55+AB106+AB153+AB164+AB175+AB186+AB197+AB208+AB219+AB230+AB241 -> 151.54535
B26: + Vay mới trong năm | S26: =+S56+S105+S152+S163+S174+S185+S196+S207+S218+S229+S240 -> 301.57349 | T26: =+T56+T105+T152+T163+T174+T185+T196+T207+T218+T229+T240 -> 273.4046 | U26: =+U56+U105+U152+U163+U174+U185+U196+U207+U218+U229+U240 -> 268.38361 | V26: =+V56+V105+V152+V163+V174+V185+V196+V207+V218+V229+V240 -> 443.63826 | W26: =+W56+W105+W152+W163+W174+W185+W196+W207+W218+W229+W240 -> 171.78522 | X26: =+X56+X105+X152+X163+X174+X185+X196+X207+X218+X229+X240 -> 139.70631 | Y26: =+Y56+Y105+Y152+Y163+Y174+Y185+Y196+Y207+Y218+Y229+Y240 -> 113.01912 | Z26: =+Z56+Z105+Z152+Z163+Z174+Z185+Z196+Z207+Z218+Z229+Z240 -> 126.43555 | ... AB26: =+AB56+AB105+AB152+AB163+AB174+AB185+AB196+AB207+AB218+AB229+AB240 -> 144.05465
B27: Dư nợ gốc cuối năm | R27: =R57 -> 119.5275 | S27: =+S57+S107+S154+S165+S176+S187+S198+S209+S220+S231+S242 -> 351.10114 | T27: =+T57+T107+T154+T165+T176+T187+T198+T209+T220+T231+T242 -> 497.00808 | U27: =+U57+U107+U154+U165+U176+U187+U198+U209+U220+U231+U242 -> 583.71521 | V27: =+V57+V107+V154+V165+V176+V187+V198+V209+V220+V231+V242 -> 814.31731 | W27: =+W57+W107+W154+W165+W176+W187+W198+W209+W220+W231+W242 -> 711.52402 | X27: =+X57+X107+X154+X165+X176+X187+X198+X209+X220+X231+X242 -> 575.66 | Y27: =+Y57+Y107+Y154+Y165+Y176+Y187+Y198+Y209+Y220+Y231+Y242 -> 445.33407 | Z27: =+Z57+Z107+Z154+Z165+Z176+Z187+Z198+Z209+Z220+Z231+Z242 -> 358.65792 | ... AB27: =+AB57+AB107+AB154+AB165+AB176+AB187+AB198+AB209+AB220+AB231+AB242 -> 344.77629
